Workbook

Sheet GENERAL
B2: INVERSIÓN PORTAFOLIO | C2: =SUM(L:L) -> 11000.586 | E2: PLUSVALÍA (%) | G2: =SUM(AB13:AB1001) -> 1.3016213 | J2: DIVIDENDO ANUAL BRUTO | N2: =SUM(AP13:AP1001) -> 0.049689274 | R2: RENTAS ANUALES BRUTAS | V2: =SUM(AN13:AN1001) -> 360.10094 | Z2: RENTAS REALES BRUTAS | AD2: =SUM(DIVIDENDOS!D:D) -> 39.773589 | AI2: % RENTAS PORTAFOLIO BRUTAS | AN2: =((V2*100)/C2)/100 -> 0.032734704
B5: VALOR PORTAFOLIO | C5: =SUM(M:M) -> #N/A | E5: GANANCIA ($) | G5: =SUM(AD13:AD1001) -> 1205.8738 | H5: =SUM(COMPRAS!I:I) -> -34.0099 | I5: =G5+H5 -> 1171.8639 | J5: DIVIDENDO ANUAL NETO | N5: =N2*0.7 -> 0.034782492 | R5: RENTAS ANUALES NETAS | V5: =V2*0.7 -> 252.07066 | Z5: RENTAS REALES NETAS | AD5: =SUM(DIVIDENDOS!E:E) -> 31.039583 | AI5: % RENTAS | AN5: =((V5*100)/C2)/100 -> 0.022914293
A8: CLAVE | B8: FIBRA | C8: Última información | D8: % Portafolio | E8: INFORMACIÓN BURSÁTIL | N8: INFORMACIÓN FUNDAMENTAL | AB8: RENTABILIDAD
B9: FIBRA | E9: Número de Títulos | F9: Costo promedio | G9: Precio de Mercado | H9: AVG Precio de Mercado 52S | I9: Cambio vs dia anterior (%) | J9: Volumen | K9: Costo Total Promedio | L9: Costo Total Compra | M9: Valor de Mercado | N9: Cap Rate Implícito | O9: AVG Cap Rate Implícito | P9: NAV por CBFI | Q9: AVG NAV por CBFI | R9: Distribución Trimestral por CBFI | S9: AVG Distribución Trimestral por CBFI | T9: Distribución Anual por CBFI | U9: AGV Distribución Anual por CBFI | V9: Loan To Value | W9: AVG Loan To Value | X9: Margen NOI | Y9: AVG Margen NOI | Z9: Margen FFO | AA9: AVG Margen FFO | AB9: Portafolio Plusvalía (%) | AC9: AVG Plusvalía (%) | AD9: Portafolio Ganancia ($) | AE9: AVG Ganancia ($) | AF9: NAV vs Precio Mercado | AG9: Dividend Yield Calculado | AH9: AVG Dividend Yield Calculado | AI9: Dividend Yield Decretado | AJ9: AVG Dividend Yield Decretado | AK9: AVG Dividend Yield | AL9: Renta Trimestral | AM9: AVG Renta Trimestral | AN9: Renta Anual | AO9: AVG Renta Anual | AP9: Dividendo Ponderado Bruto
A10: FHIPO14 | B10: FIBRA HIPOTECARIA | C10: {=IF(INDIRECT("'"&A$10&"'!"&"B10") ="",INDIRECT("'"&A$10&"'!"&"C1"),INDIRECT("'"&A$10&"'!"&"B1"))} -> 2023 Q1 | D10: =IFERROR(E10/SUM(E13:E35),0) -> 0.11079545 | E10: =SUMIFS(COMPRAS!B:B,COMPRAS!A:A,B10) -> 39 | F10: =IFERROR(AVERAGEIFS(COMPRAS!C:C,COMPRAS!A:A,B10),0) -> 16.5425 | G10: =IFERROR(yahooF(A10&".MX",1),F10) -> 16.5425 | H10: =IFERROR(__xludf.DUMMYFUNCTION("IFERROR(G10,(GOOGLEFINANCE(A10,""high52"") + GOOGLEFINANCE(A10,""low52""))/2)"),16.5425) -> 16.5425 | I10: =yahooF(A10&".MX",2) -> #ERROR! | J10: 7784 | K10: =E10*F10 -> 645.1575 | L10: =IFERROR(SUMIFS(COMPRAS!G:G,COMPRAS!A:A,B10),0) -> 637.94151 | M10: =E10*G10 -> 645.1575 | N10: {=IF(INDIRECT("'"&A$10&"'!"&"B12") ="",INDIRECT("'"&A$10&"'!"&"C12"),INDIRECT("'"&A$10&"'!"&"B12"))} | O10: {=IFERROR(AVERAGE(INDIRECT("'"&A$10&"'!"&"B12:F12")),"")} | P10: {=IF(INDIRECT("'"&A$10&"'!"&"B17") ="",INDIRECT("'"&A$10&"'!"&"C17"),INDIRECT("'"&A$10&"'!"&"B17"))} | Q10: {=IFERROR(AVERAGE(INDIRECT("'"&A$10&"'!"&"B17:F17")),"")} | R10: {=IF(INDIRECT("'"&A$10&"'!"&"B10") ="",INDIRECT("'"&A$10&"'!"&"C10"),INDIRECT("'"&A$10&"'!"&"B10"))} -> 0.2566 | S10: {=IFERROR(AVERAGE(INDIRECT("'"&A$10&"'!"&"B10:F10")),"")} -> 0.5060862 | T10: =R10*4 -> 1.0264 | U10: =S10*4 -> 2.0243448 | V10: {=IF(INDIRECT("'"&A$10&"'!"&"B15") ="",INDIRECT("'"&A$10&"'!"&"C15"),INDIRECT("'"&A$10&"'!"&"B15"))} | W10: {=IFERROR(AVERAGE(INDIRECT("'"&A$10&"'!"&"B15:F15")),"")} | X10: {=IF(INDIRECT("'"&A$10&"'!"&"B5") ="",INDIRECT("'"&A$10&"'!"&"C5"),INDIRECT("'"&A$10&"'!"&"B5"))} | Y10: {=IFERROR(AVERAGE(INDIRECT("'"&A$10&"'!"&"B5:F5")),"")} | Z10: {=IF(INDIRECT("'"&A$10&"'!"&"B7") ="",INDIRECT("'"&A$10&"'!"&"C7"),INDIRECT("'"&A$10&"'!"&"B7"))} | AA10: {=IFERROR(AVERAGE(INDIRECT("'"&A$10&"'!"&"B7:F7")),"")} | AB10: =IFERROR((G10/(L10/E10))-1,"") -> 0.011311371 | AC10: =IFERROR(U10/G10,"") -> 0.12237236 | AD10: =IFERROR(IF(M10-L10=0,"",M10-L10),"") -> 7.215993 | AE10: =IFERROR(IF(M10-K10=0,"",M10-K10),"") | AF10: =IF(P10>0,IFERROR((P10/G10)-1,""),"") | AG10: =IFERROR(T10/G10,"") -> 0.062046245 | AI10: {=IF(INDIRECT("'"&A$10&"'!"&"B16") ="",INDIRECT("'"&A$10&"'!"&"C16"),INDIRECT("'"&A$10&"'!"&"B16"))} | AJ10: {=IFERROR(AVERAGE(INDIRECT("'"&A$10&"'!"&"B16:F16")),"")} | AK10: =AVERAGE(AG10:AJ10) -> 0.062046245 | AL10: =IFERROR(IF(R10*E10=0,"",R10*E10),"") -> 10.0074 | AM10: =IFERROR(IF(S10*E10=0,"",S10*E10),"") -> 19.737362 | AN10: =IFERROR(IF(T10*E10=0,"",T10*E10),"") -> 40.0296 | AO10: =IFERROR(IF(U10*E10=0,"",U10*E10),"") -> 78.949447 | AP10: =IF(AC10*D10=0,"",AC10*D10) -> 0.013558301
A11: FCFE18 | B11: FIBRA CFE | C11: {=IF(INDIRECT("'"&A$11&"'!"&"B10") ="",INDIRECT("'"&A$11&"'!"&"C1"),INDIRECT("'"&A$11&"'!"&"B1"))} -> 2023 Q1 | D11: =IFERROR(E11/SUM(E13:E35),0) -> 0.13352273 | E11: =SUMIFS(COMPRAS!B:B,COMPRAS!A:A,B11) -> 47 | F11: =IFERROR(AVERAGEIFS(COMPRAS!C:C,COMPRAS!A:A,B11),0) -> 27.336667 | G11: =IFERROR(__xludf.DUMMYFUNCTION("GOOGLEFINANCE(A11,""price"")"),23.84) -> 23.84 | H11: =IFERROR(__xludf.DUMMYFUNCTION("(GOOGLEFINANCE(A11,""high52"") + GOOGLEFINANCE(A11,""low52""))/2"),23.03) -> 23.03 | I11: =IFERROR(__xludf.DUMMYFUNCTION("GOOGLEFINANCE(A11,""changepct"")"),0.17) -> 0.17 | J11: =IFERROR(__xludf.DUMMYFUNCTION("GOOGLEFINANCE(A11,""volume"")"),139923.0) -> 139923 | K11: =E11*F11 -> 1284.8233 | L11: =IFERROR(SUMIFS(COMPRAS!G:G,COMPRAS!A:A,B11),0) -> 1282.995 | M11: =E11*G11 -> 1120.48 | N11: {=IF(INDIRECT("'"&A$11&"'!"&"B12") ="",INDIRECT("'"&A$11&"'!"&"C12"),INDIRECT("'"&A$11&"'!"&"B12"))} | O11: {=IFERROR(AVERAGE(INDIRECT("'"&A$11&"'!"&"B12:F12")),"")} | P11: {=IF(INDIRECT("'"&A$11&"'!"&"B17") ="",INDIRECT("'"&A$11&"'!"&"C17"),INDIRECT("'"&A$11&"'!"&"B17"))} | Q11: {=IFERROR(AVERAGE(INDIRECT("'"&A$11&"'!"&"B17:F17")),"")} | R11: {=IF(INDIRECT("'"&A$11&"'!"&"B10") ="",INDIRECT("'"&A$11&"'!"&"C10"),INDIRECT("'"&A$11&"'!"&"B10"))} -> 0.575 | S11: {=IFERROR(AVERAGE(INDIRECT("'"&A$11&"'!"&"B10:F10")),0)} -> 0.7700312 | T11: =R11*4 -> 2.3 | U11: =S11*4 -> 3.0801248 | V11: {=IF(INDIRECT("'"&A$11&"'!"&"B15") ="",INDIRECT("'"&A$11&"'!"&"C15"),INDIRECT("'"&A$11&"'!"&"B15"))} | W11: {=IFERROR(AVERAGE(INDIRECT("'"&A$11&"'!"&"B15:F15")),"")} | X11: {=IF(INDIRECT("'"&A$11&"'!"&"B5") ="",INDIRECT("'"&A$11&"'!"&"C5"),INDIRECT("'"&A$11&"'!"&"B5"))} | Y11: {=IFERROR(AVERAGE(INDIRECT("'"&A$11&"'!"&"B5:F5")),0)} -> 0 | Z11: {=IF(INDIRECT("'"&A$11&"'!"&"B7") ="",INDIRECT("'"&A$11&"'!"&"C7"),INDIRECT("'"&A$11&"'!"&"B7"))} | AA11: {=IFERROR(AVERAGE(INDIRECT("'"&A$11&"'!"&"B7:F7")),0)} -> 0 | AB11: =IFERROR((G11/(L11/E11))-1,"") -> -0.12666845 | AC11: =IFERROR(U11/G11,"") -> 0.12919987 | AD11: =IFERROR(IF(M11-L11=0,"",M11-L11),"") -> -162.51499 | AE11: =IFERROR(IF(M11-K11=0,"",M11-K11),"") -> -164.34333 | AF11: =IF(P11>0,IFERROR((P11/G11)-1,""),"") | AG11: =IFERROR(T11/G11,"") -> 0.09647651 | AI11: {=IF(INDIRECT("'"&A$11&"'!"&"B16") ="",INDIRECT("'"&A$11&"'!"&"C16"),INDIRECT("'"&A$11&"'!"&"B16"))} | AJ11: {=IFERROR(AVERAGE(INDIRECT("'"&A$11&"'!"&"B16:F16")),"")} | AK11: =AVERAGE(AG11:AJ11) -> 0.09647651 | AL11: =IFERROR(IF(R11*E11=0,"",R11*E11),"") -> 27.025 | AM11: =IFERROR(IF(S11*E11=0,"",S11*E11),"") -> 36.191466 | AN11: =IFERROR(IF(T11*E11=0,"",T11*E11),"") -> 108.1 | AO11: =IFERROR(IF(U11*E11=0,"",U11*E11),"") -> 144.76587 | AP11: =IF(AC11*D11=0,"",AC11*D11) -> 0.017251118
A12: =DANHOS13!A1 -> DANHOS13 | B12: FIBRA DAHNOS | C12: {=IF(INDIRECT("'"&A$12&"'!"&"B10") ="",INDIRECT("'"&A$12&"'!"&"C1"),INDIRECT("'"&A$12&"'!"&"B1"))} -> 2023 Q1 | D12: =IFERROR(E12/SUM(E13:E35),0) -> 0.28409091 | E12: =SUMIFS(COMPRAS!B:B,COMPRAS!A:A,B12) -> 100 | F12: =IFERROR(AVERAGEIFS(COMPRAS!C:C,COMPRAS!A:A,B12),0) -> 21.99 | G12: =IFERROR(__xludf.DUMMYFUNCTION("GOOGLEFINANCE(A12,""price"")"),27.34) -> 27.34 | H12: =IFERROR(__xludf.DUMMYFUNCTION("(GOOGLEFINANCE(A12,""high52"") + GOOGLEFINANCE(A12,""low52""))/2"),28.07) -> 28.07 | I12: =IFERROR(__xludf.DUMMYFUNCTION("GOOGLEFINANCE(A12,""changepct"")"),-0.83) -> -0.83 | J12: =IFERROR(__xludf.DUMMYFUNCTION("GOOGLEFINANCE(A12,""volume"")"),514835.0) -> 514835 | K12: =E12*F12 -> 2199 | L12: =IFERROR(SUMIFS(COMPRAS!G:G,COMPRAS!A:A,B12),0) -> 2230.4731 | M12: =E12*G12 -> 2734 | N12: {=IF(INDIRECT("'"&A$12&"'!"&"B12") ="",INDIRECT("'"&A$12&"'!"&"C12"),INDIRECT("'"&A$12&"'!"&"B12"))} -> 0.069 | O12: {=IFERROR(AVERAGE(INDIRECT("'"&A$12&"'!"&"B12:F12")),"")} -> 0.068433333 | P12: {=IF(INDIRECT("'"&A$12&"'!"&"B17") ="",INDIRECT("'"&A$12&"'!"&"C17"),INDIRECT("'"&A$12&"'!"&"B17"))} -> 39.79 | Q12: {=IFERROR(AVERAGE(INDIRECT("'"&A$12&"'!"&"B17:F17")),0)} -> 39.786667 | R12: {=IF(INDIRECT("'"&A$12&"'!"&"B10") ="",INDIRECT("'"&A$12&"'!"&"C10"),INDIRECT("'"&A$12&"'!"&"B10"))} -> 0.6 | S12: {=IFERROR(AVERAGE(INDIRECT("'"&A$12&"'!"&"B10:F10")),0)} -> 0.6 | T12: =R12*4 -> 2.4 | U12: =S12*4 -> 2.4 | V12: {=IF(INDIRECT("'"&A$12&"'!"&"B15") ="",INDIRECT("'"&A$12&"'!"&"C15"),INDIRECT("'"&A$12&"'!"&"B15"))} -> 0.0926 | W12: {=IFERROR(AVERAGE(INDIRECT("'"&A$12&"'!"&"B15:F15")),"")} -> 0.0885 | X12: {=IF(INDIRECT("'"&A$12&"'!"&"B5") ="",INDIRECT("'"&A$12&"'!"&"c5"),INDIRECT("'"&A$12&"'!"&"B5"))} -> 0.753 | Y12: {=IFERROR(AVERAGE(INDIRECT("'"&A$12&"'!"&"B5:F5")),0)} -> 0.78515 | Z12: {=IF(INDIRECT("'"&A$12&"'!"&"B7") ="",INDIRECT("'"&A$12&"'!"&"C7"),INDIRECT("'"&A$12&"'!"&"B7"))} -> 0.5305 | AA12: {=IFERROR(AVERAGE(INDIRECT("'"&A$12&"'!"&"B7:F7")),0)} -> 0.5749 | AB12: =IFERROR((G12/(L12/E12))-1,"") -> 0.22574892 | AC12: =IFERROR(U12/G12,"") -> 0.087783467 | AD12: =IFERROR(IF(M12-L12=0,"",M12-L12),"") -> 503.5269 | AE12: =IFERROR(IF(M12-K12=0,"",M12-K12),"") -> 535 | AF12: =IF(P12>0,IFERROR((P12/G12)-1,""),"") -> 0.45537674 | AG12: =IFERROR(T12/G12,"") -> 0.087783467 | AI12: {=IF(INDIRECT("'"&A$12&"'!"&"B16") ="",INDIRECT("'"&A$12&"'!"&"C16"),INDIRECT("'"&A$12&"'!"&"B16"))} -> 0.09 | AJ12: {=AVERAGE(INDIRECT("'"&A$12&"'!"&"B16:F16"))} -> 0.092366667 | AK12: =AVERAGE(AG12:AJ12) -> 0.090050045 | AL12: =IFERROR(IF(R12*E12=0,"",R12*E12),"") -> 60 | AM12: =IFERROR(IF(S12*E12=0,"",S12*E12),"") -> 60 | AN12: =IFERROR(IF(T12*E12=0,"",T12*E12),"") -> 240 | AO12: =IFERROR(IF(U12*E12=0,"",U12*E12),"") -> 240 | AP12: =IF(AC12*D12=0,"",AC12*D12) -> 0.024938485
A13: =FUNO11!A1 -> FUNO11 | B13: FIBRA UNO | C13: {=IF(INDIRECT("'"&A$13&"'!"&"B10") ="",INDIRECT("'"&A$13&"'!"&"C1"),INDIRECT("'"&A$13&"'!"&"B1"))} -> 2023 Q1 | D13: =IFERROR(E13/SUM(E13:E35),0) -> 0.17045455 | E13: =SUMIFS(COMPRAS!B:B,COMPRAS!A:A,B13) -> 60 | F13: =IFERROR(AVERAGEIFS(COMPRAS!C:C,COMPRAS!A:A,B13),0) -> 24.48 | G13: =IFERROR(__xludf.DUMMYFUNCTION("GOOGLEFINANCE(A13,""price"")"),29.73) -> 29.73 | H13: =IFERROR(__xludf.DUMMYFUNCTION("(GOOGLEFINANCE(A13,""high52"") + GOOGLEFINANCE(A13,""low52""))/2"),28.21) -> 28.21 | I13: =IFERROR(__xludf.DUMMYFUNCTION("GOOGLEFINANCE(A13,""changepct"")"),-0.03) -> -0.03 | J13: =IFERROR(__xludf.DUMMYFUNCTION("GOOGLEFINANCE(A13,""volume"")"),2305818.0) -> 2305818 | K13: =E13*F13 -> 1468.8 | L13: =IFERROR(SUMIFS(COMPRAS!G:G,COMPRAS!A:A,B13),0) -> 1472.0693 | M13: =E13*G13 -> 1783.8 | N13: {=IF(INDIRECT("'"&A$13&"'!"&"B12") ="",INDIRECT("'"&A$13&"'!"&"C12"),INDIRECT("'"&A$13&"'!"&"B12"))} -> 0.0636 | O13: {=IFERROR(AVERAGE(INDIRECT("'"&A$13&"'!"&"B12:F12")),"")} -> 0.062733333 | P13: {=IF(INDIRECT("'"&A$13&"'!"&"B17") ="",INDIRECT("'"&A$13&"'!"&"C17"),INDIRECT("'"&A$13&"'!"&"B17"))} -> 50.02 | Q13: {=IFERROR(AVERAGE(INDIRECT("'"&A$13&"'!"&"B17:F17")),0)} -> 48.543333 | R13: {=IF(INDIRECT("'"&A$13&"'!"&"B10") ="",INDIRECT("'"&A$13&"'!"&"C10"),INDIRECT("'"&A$13&"'!"&"B10"))} -> 0.389133 | S13: {=IFERROR(AVERAGE(INDIRECT("'"&A$13&"'!"&"B10:F10")),0)} -> 0.6180646 | T13: =R13*4 -> 1.556532 | U13: =S13*4 -> 2.4722584 | V13: {=IF(INDIRECT("'"&A$13&"'!"&"B15") ="",INDIRECT("'"&A$13&"'!"&"C15"),INDIRECT("'"&A$13&"'!"&"B15"))} -> 0.4 | W13: {=IFERROR(AVERAGE(INDIRECT("'"&A$13&"'!"&"B15:F15")),"")} -> 0.4163 | X13: {=IF(INDIRECT("'"&A$13&"'!"&"B5") ="",INDIRECT("'"&A$13&"'!"&"C5"),INDIRECT("'"&A$13&"'!"&"B5"))} -> 0.784 | Y13: {=IFERROR(AVERAGE(INDIRECT("'"&A$13&"'!"&"B5:F5")),0)} -> 0.78674 | Z13: {=IF(INDIRECT("'"&A$13&"'!"&"B7") ="",INDIRECT("'"&A$13&"'!"&"C7"),INDIRECT("'"&A$13&"'!"&"B7"))} -> 0.348 | AA13: {=IFERROR(AVERAGE(INDIRECT("'"&A$13&"'!"&"B7:F7")),0)} -> 0.37968 | AB13: =IFERROR((G13/(L13/E13))-1,"") -> 0.21176359 | AC13: =IFERROR(U13/G13,"") -> 0.083157027 | AD13: =IFERROR(IF(M13-L13=0,"",M13-L13),"") -> 311.73069 | AE13: =IFERROR(IF(M13-K13=0,"",M13-K13),"") -> 315 | AF13: =IF(P13>0,IFERROR((P13/G13)-1,""),"") -> 0.68247561 | AG13: =IFERROR(T13/G13,"") -> 0.0523556 | AI13: {=IF(INDIRECT("'"&A$13&"'!"&"B16") ="",INDIRECT("'"&A$13&"'!"&"C16"),INDIRECT("'"&A$13&"'!"&"B16"))} -> 0.0607 | AJ13: {=AVERAGE(INDIRECT("'"&A$13&"'!"&"B16:F16"))} -> 0.071766667 | AK13: =AVERAGE(AG13:AJ13) -> 0.061607422 | AL13: =IFERROR(IF(R13*E13=0,"",R13*E13),"") -> 23.34798 | AM13: =IFERROR(IF(S13*E13=0,"",S13*E13),"") -> 37.083876 | AN13: =IFERROR(IF(T13*E13=0,"",T13*E13),"") -> 93.39192 | AO13: =IFERROR(IF(U13*E13=0,"",U13*E13),"") -> 148.3355 | AP13: =IF(AC13*D13=0,"",AC13*D13) -> 0.014174493
A14: =FMTY14!A1 -> FMTY14 | B14: FIBRA MONTEREY | C14: {=IF(INDIRECT("'"&A$14&"'!"&"B10") ="",INDIRECT("'"&A$14&"'!"&"C1"),INDIRECT("'"&A$14&"'!"&"B1"))} -> 2023 Q1 | D14: =IFERROR(E14/SUM(E13:E35),0) -> 0.4375 | E14: =SUMIFS(COMPRAS!B:B,COMPRAS!A:A,B14) -> 154 | F14: =IFERROR(AVERAGEIFS(COMPRAS!C:C,COMPRAS!A:A,B14),0) -> 11.921 | G14: =IFERROR(__xludf.DUMMYFUNCTION("GOOGLEFINANCE(A14,""price"")"),14.61) -> 14.61 | H14: =IFERROR(__xludf.DUMMYFUNCTION("(GOOGLEFINANCE(A14,""high52"") + GOOGLEFINANCE(A14,""low52""))/2"),14.395) -> 14.395 | I14: =IFERROR(__xludf.DUMMYFUNCTION("GOOGLEFINANCE(A14,""changepct"")"),0.69) -> 0.69 | J14: =IFERROR(__xludf.DUMMYFUNCTION("GOOGLEFINANCE(A14,""volume"")"),6200822.0) -> 6200822 | K14: =E14*F14 -> 1835.834 | L14: =IFERROR(SUMIFS(COMPRAS!G:G,COMPRAS!A:A,B14),0) -> 1798.4981 | M14: =E14*G14 -> 2249.94 | N14: {=IF(INDIRECT("'"&A$14&"'!"&"B12")="",INDIRECT("'"&A$14&"'!"&"C12"),INDIRECT("'"&A$14&"'!"&"B12"))} -> 0.0475 | O14: {=IFERROR(AVERAGE(INDIRECT("'"&A$14&"'!"&"B12:F12")),"")} -> 0.064433333 | P14: {=IF(INDIRECT("'"&A$14&"'!"&"B17") ="",INDIRECT("'"&A$14&"'!"&"C17"),INDIRECT("'"&A$14&"'!"&"B17"))} -> 12.08 | Q14: {=IFERROR(AVERAGE(INDIRECT("'"&A$14&"'!"&"B17:F17")),0)} -> 12.773333 | R14: {=IF(INDIRECT("'"&A$14&"'!"&"B10") ="",INDIRECT("'"&A$14&"'!"&"C10"),INDIRECT("'"&A$14&"'!"&"B10"))} -> 0 | S14: {=IFERROR(AVERAGE(INDIRECT("'"&A$14&"'!"&"B10:F10")),0)} -> 0.2125466 | T14: =R14*4 -> 0 | U14: =S14*4 -> 0.8501864 | V14: {=IF(INDIRECT("'"&A$14&"'!"&"B15") ="",INDIRECT("'"&A$14&"'!"&"C15"),INDIRECT("'"&A$14&"'!"&"B15"))} -> 0.3685 | W14: {=IFERROR(AVERAGE(INDIRECT("'"&A$14&"'!"&"B15:F15")),"")} -> 0.2816 | X14: {=IF(INDIRECT("'"&A$14&"'!"&"B5") ="",INDIRECT("'"&A$14&"'!"&"C5"),INDIRECT("'"&A$14&"'!"&"B5"))} -> 0.8872 | Y14: {=IFERROR(AVERAGE(INDIRECT("'"&A$14&"'!"&"B5:F5")),0)} -> 0.88378 | Z14: {=IF(INDIRECT("'"&A$14&"'!"&"B7") ="",INDIRECT("'"&A$14&"'!"&"C7"),INDIRECT("'"&A$14&"'!"&"B7"))} -> 0.9334 | AA14: {=IFERROR(AVERAGE(INDIRECT("'"&A$14&"'!"&"B7:F7")),0)} -> 0.77808 | AB14: =IFERROR((G14/(L14/E14))-1,"") -> 0.25101049 | AC14: =IFERROR(U14/G14,"") -> 0.058192088 | AD14: =IFERROR(IF(M14-L14=0,"",M14-L14),"") -> 451.44189 | AE14: =IFERROR(IF(M14-K14=0,"",M14-K14),"") -> 414.106 | AF14: =IF(P14>0,IFERROR((P14/G14)-1,""),"") -> -0.17316906 | AG14: =IFERROR(T14/G14,"") -> 0 | AI14: {=IF(INDIRECT("'"&A$14&"'!"&"B16") ="",INDIRECT("'"&A$14&"'!"&"C16"),INDIRECT("'"&A$14&"'!"&"B16"))} -> 0.0735 | AJ14: {=AVERAGE(INDIRECT("'"&A$14&"'!"&"B16:F16"))} -> 0.0777 | AK14: =AVERAGE(AG14:AJ14) -> 0.0504 | AL14: =IFERROR(IF(R14*E14=0,"",R14*E14),"") | AM14: =IFERROR(IF(S14*E14=0,"",S14*E14),"") -> 32.732176 | AN14: =IFERROR(IF(T14*E14=0,"",T14*E14),"") | AO14: =IFERROR(IF(U14*E14=0,"",U14*E14),"") -> 130.92871 | AP14: =IF(AC14*D14=0,"",AC14*D14) -> 0.025459038
A15: FNOVA17 | B15: FIBRA NOVA | C15: {=IF(INDIRECT("'"&A$15&"'!"&"B10") ="",INDIRECT("'"&A$15&"'!"&"C1"),INDIRECT("'"&A$15&"'!"&"B1"))} -> 2023 Q1 | D15: =IFERROR(E15/SUM(E13:E35),0) -> 0.21022727 | E15: =SUMIFS(COMPRAS!B:B,COMPRAS!A:A,B15) -> 74 | F15: =IFERROR(AVERAGEIFS(COMPRAS!C:C,COMPRAS!A:A,B15),0) -> 29.7325 | G15: =IFERROR(__xludf.DUMMYFUNCTION("GOOGLEFINANCE(A15,""price"")"),"#N/A") -> #N/A | H15: =IFERROR(__xludf.DUMMYFUNCTION("(GOOGLEFINANCE(A15,""high52"") + GOOGLEFINANCE(A15,""low52""))/2"),"#N/A") -> #N/A | I15: =IFERROR(__xludf.DUMMYFUNCTION("GOOGLEFINANCE(A15,""changepct"")"),"#N/A") -> #N/A | J15: =IFERROR(__xludf.DUMMYFUNCTION("GOOGLEFINANCE(A15,""volume"")"),"#N/A") -> #N/A | K15: =E15*F15 -> 2200.205 | L15: =IFERROR(SUMIFS(COMPRAS!G:G,COMPRAS!A:A,B15),0) -> 2168.2007 | M15: =E15*G15 -> #N/A | N15: {=IF(INDIRECT("'"&A$15&"'!"&"B12") ="",INDIRECT("'"&A$15&"'!"&"C12"),INDIRECT("'"&A$15&"'!"&"B12"))} -> 0.0762 | O15: {=IFERROR(AVERAGE(INDIRECT("'"&A$15&"'!"&"B12:F12")),"")} -> 0.076833333 | P15: {=IF(INDIRECT("'"&A$15&"'!"&"B17") ="",INDIRECT("'"&A$15&"'!"&"C17"),INDIRECT("'"&A$15&"'!"&"B17"))} -> 20.41 | Q15: {=IFERROR(AVERAGE(INDIRECT("'"&A$15&"'!"&"B17:F17")),0)} -> 21.346667 | R15: {=IF(INDIRECT("'"&A$15&"'!"&"B10") ="",INDIRECT("'"&A$15&"'!"&"C10"),INDIRECT("'"&A$15&"'!"&"B10"))} -> 0.5797 | S15: {=IFERROR(AVERAGE(INDIRECT("'"&A$15&"'!"&"B10:F10")),0)} -> 0.4594304 | T15: =R15*4 -> 2.3188 | U15: =S15*4 -> 1.8377216 | V15: {=IF(INDIRECT("'"&A$15&"'!"&"B15") ="",INDIRECT("'"&A$15&"'!"&"C15"),INDIRECT("'"&A$15&"'!"&"B15"))} -> 0.4783 | W15: {=IFERROR(AVERAGE(INDIRECT("'"&A$15&"'!"&"B15:F15")),"")} -> 0.46003333 | X15: {=IF(INDIRECT("'"&A$15&"'!"&"B5") ="",INDIRECT("'"&A$15&"'!"&"C5"),INDIRECT("'"&A$15&"'!"&"B5"))} -> 0.9727 | Y15: {=IFERROR(AVERAGE(INDIRECT("'"&A$15&"'!"&"B5:F5")),0)} -> 0.97156 | Z15: {=IF(INDIRECT("'"&A$15&"'!"&"B7") ="",INDIRECT("'"&A$15&"'!"&"C7"),INDIRECT("'"&A$15&"'!"&"B7"))} -> 0.8104 | AA15: {=IFERROR(AVERAGE(INDIRECT("'"&A$15&"'!"&"B7:F7")),0)} -> 0.80972 | AB15: =IFERROR((G15/(L15/E15))-1,"") | AC15: =IFERROR(U15/G15,"") | AD15: =IFERROR(IF(M15-L15=0,"",M15-L15),"") | AE15: =IFERROR(IF(M15-K15=0,"",M15-K15),"") | AF15: =IF(P15>0,IFERROR((P15/G15)-1,""),"") | AG15: =IFERROR(T15/G15,"") | AI15: {=IF(INDIRECT("'"&A$15&"'!"&"B16") ="",INDIRECT("'"&A$15&"'!"&"C16"),INDIRECT("'"&A$15&"'!"&"B16"))} -> 0.0756 | AJ15: {=IFERROR(AVERAGE(INDIRECT("'"&A$15&"'!"&"B16:F16")),"")} -> 0.070866667 | AK15: =AVERAGE(AG15:AJ15) -> 0.073233333 | AL15: =IFERROR(IF(R15*E15=0,"",R15*E15),"") -> 42.8978 | AM15: =IFERROR(IF(S15*E15=0,"",S15*E15),"") -> 33.99785 | AN15: =IFERROR(IF(T15*E15=0,"",T15*E15),"") -> 171.5912 | AO15: =IFERROR(IF(U15*E15=0,"",U15*E15),"") -> 135.9914 | AP15: =IF(AC15*D15=0,"",AC15*D15)
A16: =FIBRAMQ12!A1 -> FIBRAMQ12 | B16: FIBRA MACQUARIE | C16: {=IF(INDIRECT("'"&A$16&"'!"&"B10") ="",INDIRECT("'"&A$16&"'!"&"C1"),INDIRECT("'"&A$16&"'!"&"B1"))} -> 2023 Q1 | D16: =IFERROR(E16/SUM(E13:E35),0) -> 0.090909091 | E16: =SUMIFS(COMPRAS!B:B,COMPRAS!A:A,B16) -> 32 | F16: =IFERROR(AVERAGEIFS(COMPRAS!C:C,COMPRAS!A:A,B16),0) -> 28.745714 | G16: =IFERROR(__xludf.DUMMYFUNCTION("GOOGLEFINANCE(A16,""price"")"),43.51) -> 43.51 | H16: =IFERROR(__xludf.DUMMYFUNCTION("(GOOGLEFINANCE(A16,""high52"") + GOOGLEFINANCE(A16,""low52""))/2"),37.415) -> 37.415 | I16: =IFERROR(__xludf.DUMMYFUNCTION("GOOGLEFINANCE(A16,""changepct"")"),0.97) -> 0.97 | J16: =IFERROR(__xludf.DUMMYFUNCTION("GOOGLEFINANCE(A16,""volume"")"),814553.0) -> 814553 | K16: =E16*F16 -> 919.86286 | L16: =IFERROR(SUMIFS(COMPRAS!G:G,COMPRAS!A:A,B16),0) -> 921.52791 | M16: =E16*G16 -> 1392.32 | N16: {=IF(INDIRECT("'"&A$16&"'!"&"B12") ="",INDIRECT("'"&A$16&"'!"&"C12"),INDIRECT("'"&A$16&"'!"&"B12"))} -> 0.0693 | O16: {=IFERROR(AVERAGE(INDIRECT("'"&A$16&"'!"&"B12:F12")),"")} -> 0.06895 | P16: {=IF(INDIRECT("'"&A$16&"'!"&"B17") ="",INDIRECT("'"&A$16&"'!"&"C17"),INDIRECT("'"&A$16&"'!"&"B17"))} -> 45.39 | Q16: {=IFERROR(AVERAGE(INDIRECT("'"&A$16&"'!"&"B17:F17")),0)} -> 45.81 | R16: {=IF(INDIRECT("'"&A$16&"'!"&"B10") ="",INDIRECT("'"&A$16&"'!"&"C10"),INDIRECT("'"&A$16&"'!"&"B10"))} -> 0.525 | S16: {=IFERROR(AVERAGE(INDIRECT("'"&A$16&"'!"&"B10:F10")),0)} -> 0.6807648 | T16: =R16*4 -> 2.1 | U16: =S16*4 -> 2.7230592 | V16: {=IF(INDIRECT("'"&A$16&"'!"&"B15") ="",INDIRECT("'"&A$16&"'!"&"C15"),INDIRECT("'"&A$16&"'!"&"B15"))} -> 0.3167 | W16: {=IFERROR(AVERAGE(INDIRECT("'"&A$16&"'!"&"B15:F15")),"")} -> 0.3185 | X16: {=IF(INDIRECT("'"&A$16&"'!"&"B5") ="",INDIRECT("'"&A$16&"'!"&"C5"),INDIRECT("'"&A$16&"'!"&"B5"))} -> 0.9013 | Y16: {=IFERROR(AVERAGE(INDIRECT("'"&A$16&"'!"&"B5:F5")),0)} -> 0.920675 | Z16: {=IF(INDIRECT("'"&A$16&"'!"&"B7") ="",INDIRECT("'"&A$16&"'!"&"C7"),INDIRECT("'"&A$16&"'!"&"B7"))} -> 0.6011 | AA16: {=IFERROR(AVERAGE(INDIRECT("'"&A$16&"'!"&"B7:F7")),0)} -> 0.618525 | AB16: =IFERROR((G16/(L16/E16))-1,"") -> 0.51088208 | AC16: =IFERROR(U16/G16,"") -> 0.062584675 | AD16: =IFERROR(IF(M16-L16=0,"",M16-L16),"") -> 470.79209 | AE16: =IFERROR(IF(M16-K16=0,"",M16-K16),"") -> 472.45714 | AF16: =IF(P16>0,IFERROR((P16/G16)-1,""),"") -> 0.043208458 | AG16: =IFERROR(T16/G16,"") -> 0.048264767 | AI16: {=IF(INDIRECT("'"&A$16&"'!"&"B16") ="",INDIRECT("'"&A$16&"'!"&"C16"),INDIRECT("'"&A$16&"'!"&"B16"))} -> 0.0643 | AJ16: {=AVERAGE(INDIRECT("'"&A$16&"'!"&"B16:F16"))} -> 0.06805 | AK16: =AVERAGE(AG16:AJ16) -> 0.060204922 | AL16: =IFERROR(IF(R16*E16=0,"",R16*E16),"") -> 16.8 | AM16: =IFERROR(IF(S16*E16=0,"",S16*E16),"") -> 21.784474 | AN16: =IFERROR(IF(T16*E16=0,"",T16*E16),"") -> 67.2 | AO16: =IFERROR(IF(U16*E16=0,"",U16*E16),"") -> 87.137894 | AP16: =IF(AC16*D16=0,"",AC16*D16) -> 0.0056895159
A17: FIBRAUP18 | B17: FIBRA UPSITE | C17: {=IF(INDIRECT("'"&A$17&"'!"&"B10") ="",INDIRECT("'"&A$17&"'!"&"C1"),INDIRECT("'"&A$17&"'!"&"B1"))} -> 2022 Q4 | D17: =IFERROR(E17/SUM(E13:E35),0) -> 0 | E17: =SUMIFS(COMPRAS!B:B,COMPRAS!A:A,B17) -> 0 | F17: =IFERROR(AVERAGEIFS(COMPRAS!C:C,COMPRAS!A:A,B17),0) -> 0 | G17: =IFERROR(__xludf.DUMMYFUNCTION("GOOGLEFINANCE(A17,""price"")"),38.8) -> 38.8 | H17: =IFERROR(__xludf.DUMMYFUNCTION("(GOOGLEFINANCE(A17,""high52"") + GOOGLEFINANCE(A17,""low52""))/2"),36.0) -> 36 | I17: =IFERROR(__xludf.DUMMYFUNCTION("GOOGLEFINANCE(A17,""changepct"")"),0.0) -> 0 | J17: =IFERROR(__xludf.DUMMYFUNCTION("GOOGLEFINANCE(A17,""volume"")"),17.0) -> 17 | K17: =E17*F17 -> 0 | L17: =IFERROR(SUMIFS(COMPRAS!G:G,COMPRAS!A:A,B17),0) -> 0 | M17: =E17*G17 -> 0 | N17: {=IF(INDIRECT("'"&A$17&"'!"&"B12") ="",INDIRECT("'"&A$17&"'!"&"C12"),INDIRECT("'"&A$17&"'!"&"B12"))} -> 0.0427 | O17: {=IFERROR(AVERAGE(INDIRECT("'"&A$17&"'!"&"B12:F12")),"")} -> 0.0409 | P17: {=IF(INDIRECT("'"&A$17&"'!"&"B17") ="",INDIRECT("'"&A$17&"'!"&"C17"),INDIRECT("'"&A$17&"'!"&"B17"))} -> 53.82 | Q17: {=IFERROR(AVERAGE(INDIRECT("'"&A$17&"'!"&"B17:F17")),0)} -> 53.215 | R17: {=IF(INDIRECT("'"&A$17&"'!"&"B10") ="",INDIRECT("'"&A$17&"'!"&"C10"),INDIRECT("'"&A$17&"'!"&"B10"))} -> 0 | S17: {=IFERROR(AVERAGE(INDIRECT("'"&A$17&"'!"&"B10:F10")),0)} -> 0 | T17: =R17*4 -> 0 | U17: =S17*4 -> 0 | V17: {=IF(INDIRECT("'"&A$17&"'!"&"B15") ="",INDIRECT("'"&A$17&"'!"&"C15"),INDIRECT("'"&A$17&"'!"&"B15"))} -> 0.2454 | W17: {=IFERROR(AVERAGE(INDIRECT("'"&A$17&"'!"&"B15:F15")),"")} -> 0.25075 | X17: {=IF(INDIRECT("'"&A$17&"'!"&"B5") ="",INDIRECT("'"&A$17&"'!"&"C5"),INDIRECT("'"&A$17&"'!"&"B5"))} -> 0.8022 | Y17: {=IFERROR(AVERAGE(INDIRECT("'"&A$17&"'!"&"B5:F5")),0)} -> 0.811475 | Z17: {=IF(INDIRECT("'"&A$17&"'!"&"B7") ="",INDIRECT("'"&A$17&"'!"&"C7"),INDIRECT("'"&A$17&"'!"&"B7"))} -> 0.1631 | AA17: {=IFERROR(AVERAGE(INDIRECT("'"&A$17&"'!"&"B7:F7")),0)} -> -0.818725 | AB17: =IFERROR((G17/(L17/E17))-1,"") | AC17: =IFERROR(U17/G17,"") -> 0 | AD17: =IFERROR(IF(M17-L17=0,"",M17-L17),"") | AE17: =IFERROR(IF(M17-K17=0,"",M17-K17),"") | AF17: =IF(P17>0,IFERROR((P17/G17)-1,""),"") -> 0.3871134 | AG17: =IFERROR(T17/G17,"") -> 0 | AI17: {=IF(INDIRECT("'"&A$17&"'!"&"B16") ="",INDIRECT("'"&A$17&"'!"&"C16"),INDIRECT("'"&A$17&"'!"&"B16"))} -> 0 | AJ17: {=IFERROR(AVERAGE(INDIRECT("'"&A$17&"'!"&"B16:F16")),"")} -> 0 | AK17: =AVERAGE(AG17:AJ17) -> 0 | AL17: =IFERROR(IF(R17*E17=0,"",R17*E17),"") | AM17: =IFERROR(IF(S17*E17=0,"",S17*E17),"") | AN17: =IFERROR(IF(T17*E17=0,"",T17*E17),"") | AO17: =IFERROR(IF(U17*E17=0,"",U17*E17),"") | AP17: =IF(AC17*D17=0,"",AC17*D17)
A18: FVIA16 | B18: FIBRA VIA | C18: {=IF(INDIRECT("'"&A$18&"'!"&"B10") ="",INDIRECT("'"&A$18&"'!"&"C1"),INDIRECT("'"&A$18&"'!"&"B1"))} -> 2022 Q4 | D18: =IFERROR(E18/SUM(E13:E35),0) -> 0.039772727 | E18: =SUMIFS(COMPRAS!B:B,COMPRAS!A:A,B18) -> 14 | F18: =IFERROR(AVERAGEIFS(COMPRAS!C:C,COMPRAS!A:A,B18),0) -> 25.45 | G18: =IFERROR(__xludf.DUMMYFUNCTION("GOOGLEFINANCE(A18,""price"")"),19.5) -> 19.5 | H18: =IFERROR(__xludf.DUMMYFUNCTION("IFERROR(G18,(GOOGLEFINANCE(A18,""high52"") + GOOGLEFINANCE(A18,""low52""))/2)"),19.5) -> 19.5 | I18: =IFERROR(__xludf.DUMMYFUNCTION("GOOGLEFINANCE(A18,""changepct"")"),2.63) -> 2.63 | J18: =IFERROR(__xludf.DUMMYFUNCTION("GOOGLEFINANCE(A18,""volume"")"),706.0) -> 706 | K18: =E18*F18 -> 356.3 | L18: =IFERROR(SUMIFS(COMPRAS!G:G,COMPRAS!A:A,B18),0) -> 357.40453 | M18: =E18*G18 -> 273 | N18: {=IF(INDIRECT("'"&A$18&"'!"&"B12") ="",INDIRECT("'"&A$18&"'!"&"C12"),INDIRECT("'"&A$18&"'!"&"B12"))} | O18: {=IFERROR(AVERAGE(INDIRECT("'"&A$18&"'!"&"B12:F12")),"")} | P18: {=IF(INDIRECT("'"&A$18&"'!"&"B17") ="",INDIRECT("'"&A$18&"'!"&"C17"),INDIRECT("'"&A$18&"'!"&"B17"))} | Q18: {=IFERROR(AVERAGE(INDIRECT("'"&A$18&"'!"&"B17:F17")),"")} | R18: {=IF(INDIRECT("'"&A$18&"'!"&"B10") ="",INDIRECT("'"&A$18&"'!"&"C10"),INDIRECT("'"&A$18&"'!"&"B10"))} -> 0.480904 | S18: {=IFERROR(AVERAGE(INDIRECT("'"&A$18&"'!"&"B10:F10")),"")} -> 0.4712025 | T18: =R18*4 -> 1.923616 | U18: =S18*4 -> 1.88481 | V18: {=IF(INDIRECT("'"&A$18&"'!"&"B15") ="",INDIRECT("'"&A$18&"'!"&"C15"),INDIRECT("'"&A$18&"'!"&"B15"))} | W18: {=IFERROR(AVERAGE(INDIRECT("'"&A$18&"'!"&"B15:F15")),"")} | X18: {=IF(INDIRECT("'"&A$18&"'!"&"B5") ="",INDIRECT("'"&A$18&"'!"&"C5"),INDIRECT("'"&A$18&"'!"&"B5"))} | Y18: {=IFERROR(AVERAGE(INDIRECT("'"&A$18&"'!"&"B5:F5")),"")} | Z18: {=IF(INDIRECT("'"&A$18&"'!"&"B7") ="",INDIRECT("'"&A$18&"'!"&"C7"),INDIRECT("'"&A$18&"'!"&"B7"))} | AA18: {=IFERROR(AVERAGE(INDIRECT("'"&A$18&"'!"&"B7:F7")),"")} | AB18: =IFERROR((G18/(L18/E18))-1,"") -> -0.23615965 | AC18: =IFERROR(U18/G18,"") -> 0.096656923 | AD18: =IFERROR(IF(M18-L18=0,"",M18-L18),"") -> -84.40453 | AE18: =IFERROR(IF(M18-K18=0,"",M18-K18),"") -> -83.3 | AF18: =IF(P18>0,IFERROR((P18/G18)-1,""),"") | AG18: =IFERROR(T18/G18,"") -> 0.098646974 | AI18: {=IF(INDIRECT("'"&A$18&"'!"&"B16") ="",INDIRECT("'"&A$18&"'!"&"C16"),INDIRECT("'"&A$18&"'!"&"B16"))} | AJ18: {=IFERROR(AVERAGE(INDIRECT("'"&A$18&"'!"&"B16:F16")),"")} | AK18: =AVERAGE(AG18:AJ18) -> 0.098646974 | AL18: =IFERROR(IF(R18*E18=0,"",R18*E18),"") -> 6.732656 | AM18: =IFERROR(IF(S18*E18=0,"",S18*E18),"") -> 6.596835 | AN18: =IFERROR(IF(T18*E18=0,"",T18*E18),"") -> 26.930624 | AO18: =IFERROR(IF(U18*E18=0,"",U18*E18),"") -> 26.38734 | AP18: =IF(AC18*D18=0,"",AC18*D18) -> 0.0038443094
A19: FSHOP13 | B19: FIBRA SHOP | C19: {=IF(INDIRECT("'"&A$19&"'!"&"B10") ="",INDIRECT("'"&A$19&"'!"&"C1"),INDIRECT("'"&A$19&"'!"&"B1"))} -> 2023 Q1 | D19: =IFERROR(E19/SUM(E13:E35),0) -> 0.036931818 | E19: =SUMIFS(COMPRAS!B:B,COMPRAS!A:A,B19) -> 13 | F19: =IFERROR(AVERAGEIFS(COMPRAS!C:C,COMPRAS!A:A,B19),0) -> 6.0528571 | G19: =IFERROR(__xludf.DUMMYFUNCTION("GOOGLEFINANCE(A19,""price"")"),12.49) -> 12.49 | H19: =IFERROR(__xludf.DUMMYFUNCTION("(GOOGLEFINANCE(A19,""high52"") + GOOGLEFINANCE(A19,""low52""))/2"),10.350000000000001) -> 10.35 | I19: =IFERROR(__xludf.DUMMYFUNCTION("GOOGLEFINANCE(A19,""changepct"")"),-0.4) -> -0.4 | J19: =IFERROR(__xludf.DUMMYFUNCTION("GOOGLEFINANCE(A19,""volume"")"),210011.0) -> 210011 | K19: =E19*F19 -> 78.687143 | L19: =IFERROR(SUMIFS(COMPRAS!G:G,COMPRAS!A:A,B19),0) -> 78.452451 | M19: =E19*G19 -> 162.37 | N19: {=IF(INDIRECT("'"&A$19&"'!"&"B12") ="",INDIRECT("'"&A$19&"'!"&"C12"),INDIRECT("'"&A$19&"'!"&"B12"))} -> 0.0695 | O19: {=IFERROR(AVERAGE(INDIRECT("'"&A$19&"'!"&"B12:F12")),"")} -> 0.067366667 | P19: {=IF(INDIRECT("'"&A$19&"'!"&"B17") ="",INDIRECT("'"&A$19&"'!"&"C17"),INDIRECT("'"&A$19&"'!"&"B17"))} -> 28.08 | Q19: {=IFERROR(AVERAGE(INDIRECT("'"&A$19&"'!"&"B17:F17")),0)} -> 27.21 | R19: {=IF(INDIRECT("'"&A$19&"'!"&"B10") ="",INDIRECT("'"&A$19&"'!"&"C10"),INDIRECT("'"&A$19&"'!"&"B10"))} -> 0 | S19: {=IFERROR(AVERAGE(INDIRECT("'"&A$19&"'!"&"B10:F10")),0)} -> 0.0218618 | T19: =R19*4 -> 0 | U19: =S19*4 -> 0.0874472 | V19: {=IF(INDIRECT("'"&A$19&"'!"&"B15") ="",INDIRECT("'"&A$19&"'!"&"C15"),INDIRECT("'"&A$19&"'!"&"B15"))} -> 0.4535 | W19: {=IFERROR(AVERAGE(INDIRECT("'"&A$19&"'!"&"B15:F15")),"")} -> 0.44513333 | X19: {=IF(INDIRECT("'"&A$19&"'!"&"B5") ="",INDIRECT("'"&A$19&"'!"&"C5"),INDIRECT("'"&A$19&"'!"&"B5"))} -> 0.7886 | Y19: {=IFERROR(AVERAGE(INDIRECT("'"&A$19&"'!"&"B5:F5")),0)} -> 0.77588 | Z19: {=IF(INDIRECT("'"&A$19&"'!"&"B7") ="",INDIRECT("'"&A$19&"'!"&"C7"),INDIRECT("'"&A$19&"'!"&"B7"))} -> 0.1722 | AA19: {=IFERROR(AVERAGE(INDIRECT("'"&A$19&"'!"&"B7:F7")),0)} -> 0.24642 | AB19: =IFERROR((G19/(L19/E19))-1,"") -> 1.0696613 | AC19: =IFERROR(U19/G19,"") -> 0.0070013771 | AD19: =IFERROR(IF(M19-L19=0,"",M19-L19),"") -> 83.917549 | AE19: =IFERROR(IF(M19-K19=0,"",M19-K19),"") -> 83.682857 | AF19: =IF(P19>0,IFERROR((P19/G19)-1,""),"") -> 1.2481986 | AG19: =IFERROR(T19/G19,"") -> 0 | AI19: {=IF(INDIRECT("'"&A$19&"'!"&"B16") ="",INDIRECT("'"&A$19&"'!"&"C16"),INDIRECT("'"&A$19&"'!"&"B16"))} -> 0 | AJ19: {=AVERAGE(INDIRECT("'"&A$19&"'!"&"B16:F16"))} -> 0.034366667 | AK19: =AVERAGE(AG19:AJ19) -> 0.011455556 | AL19: =IFERROR(IF(R19*E19=0,"",R19*E19),"") | AM19: =IFERROR(IF(S19*E19=0,"",S19*E19),"") -> 0.2842034 | AN19: =IFERROR(IF(T19*E19=0,"",T19*E19),"") | AO19: =IFERROR(IF(U19*E19=0,"",U19*E19),"") -> 1.1368136 | AP19: =IF(AC19*D19=0,"",AC19*D19) -> 0.00025857359
A20: FINN13 | B20: FIBRA INN | C20: {=IF(INDIRECT("'"&A$20&"'!"&"B10") ="",INDIRECT("'"&A$20&"'!"&"C1"),INDIRECT("'"&A$20&"'!"&"B1"))} -> 2023 Q1 | D20: =IFERROR(E20/SUM(E13:E35),0) -> 0.011363636 | E20: =SUMIFS(COMPRAS!B:B,COMPRAS!A:A,B20) -> 4 | F20: =IFERROR(AVERAGEIFS(COMPRAS!C:C,COMPRAS!A:A,B20),0) -> 5.71 | G20: =IFERROR(__xludf.DUMMYFUNCTION("GOOGLEFINANCE(A20,""price"")"),5.1) -> 5.1 | H20: =IFERROR(__xludf.DUMMYFUNCTION("(GOOGLEFINANCE(A20,""high52"") + GOOGLEFINANCE(A20,""low52""))/2"),5.1899999999999995) -> 5.19 | I20: =IFERROR(__xludf.DUMMYFUNCTION("GOOGLEFINANCE(A20,""changepct"")"),0.0) -> 0 | J20: =IFERROR(__xludf.DUMMYFUNCTION("GOOGLEFINANCE(A20,""volume"")"),225136.0) -> 225136 | K20: =E20*F20 -> 22.84 | L20: =IFERROR(SUMIFS(COMPRAS!G:G,COMPRAS!A:A,B20),0) -> 22.911375 | M20: =E20*G20 -> 20.4 | N20: {=IF(INDIRECT("'"&A$20&"'!"&"B12") ="",INDIRECT("'"&A$20&"'!"&"C12"),INDIRECT("'"&A$20&"'!"&"B12"))} -> 0.0748 | O20: {=IFERROR(AVERAGE(INDIRECT("'"&A$20&"'!"&"B12:F12")),"")} -> 0.075566667 | P20: {=IF(INDIRECT("'"&A$20&"'!"&"B17") ="",INDIRECT("'"&A$20&"'!"&"C17"),INDIRECT("'"&A$20&"'!"&"B17"))} -> 15.34 | Q20: {=IFERROR(AVERAGE(INDIRECT("'"&A$20&"'!"&"B17:F17")),0)} -> 15.05 | R20: {=IF(INDIRECT("'"&A$20&"'!"&"B10") ="",INDIRECT("'"&A$20&"'!"&"C10"),INDIRECT("'"&A$20&"'!"&"B10"))} -> 0.04 | S20: {=IFERROR(AVERAGE(INDIRECT("'"&A$20&"'!"&"B10:F10")),0)} -> 0.025138 | T20: =R20*4 -> 0.16 | U20: =S20*4 -> 0.100552 | V20: {=IF(INDIRECT("'"&A$20&"'!"&"B15") ="",INDIRECT("'"&A$20&"'!"&"C15"),INDIRECT("'"&A$20&"'!"&"B15"))} -> 0.3353 | W20: {=IFERROR(AVERAGE(INDIRECT("'"&A$20&"'!"&"B15:F15")),"")} -> 0.33953333 | X20: {=IF(INDIRECT("'"&A$20&"'!"&"B5") ="",INDIRECT("'"&A$20&"'!"&"C5"),INDIRECT("'"&A$20&"'!"&"B5"))} -> 0.3359 | Y20: {=IFERROR(AVERAGE(INDIRECT("'"&A$20&"'!"&"B5:F5")),0)} -> 0.32938 | Z20: {=IF(INDIRECT("'"&A$20&"'!"&"B7") ="",INDIRECT("'"&A$20&"'!"&"C7"),INDIRECT("'"&A$20&"'!"&"B7"))} -> 0.0852 | AA20: {=IFERROR(AVERAGE(INDIRECT("'"&A$20&"'!"&"B7:F7")),0)} -> 0.06452 | AB20: =IFERROR((G20/(L20/E20))-1,"") -> -0.10961258 | AC20: =IFERROR(U20/G20,"") -> 0.019716078 | AD20: =IFERROR(IF(M20-L20=0,"",M20-L20),"") -> -2.511375 | AE20: =IFERROR(IF(M20-K20=0,"",M20-K20),"") -> -2.44 | AF20: =IF(P20>0,IFERROR((P20/G20)-1,""),"") -> 2.0078431 | AG20: =IFERROR(T20/G20,"") -> 0.031372549 | AI20: {=IF(INDIRECT("'"&A$20&"'!"&"B16") ="",INDIRECT("'"&A$20&"'!"&"C16"),INDIRECT("'"&A$20&"'!"&"B16"))} -> 0.0262 | AJ20: {=IFERROR(AVERAGE(INDIRECT("'"&A$20&"'!"&"B16:F16")),"")} -> 0.0238 | AK20: =AVERAGE(AG20:AJ20) -> 0.027124183 | AL20: =IFERROR(IF(R20*E20=0,"",R20*E20),"") -> 0.16 | AM20: =IFERROR(IF(S20*E20=0,"",S20*E20),"") -> 0.100552 | AN20: =IFERROR(IF(T20*E20=0,"",T20*E20),"") -> 0.64 | AO20: =IFERROR(IF(U20*E20=0,"",U20*E20),"") -> 0.402208 | AP20: =IF(AC20*D20=0,"",AC20*D20) -> 0.00022404635
A21: FPLUS16 | B21: FIBRA PLUS | C21: {=IF(INDIRECT("'"&A$21&"'!"&"B10") ="",INDIRECT("'"&A$21&"'!"&"C1"),INDIRECT("'"&A$21&"'!"&"B1"))} -> 2023 Q1 | D21: =IFERROR(E21/SUM(E13:E35),0) -> 0.0028409091 | E21: =SUMIFS(COMPRAS!B:B,COMPRAS!A:A,B21) -> 1 | F21: =IFERROR(AVERAGEIFS(COMPRAS!C:C,COMPRAS!A:A,B21),0) -> 6.4866667 | G21: =IFERROR(__xludf.DUMMYFUNCTION("GOOGLEFINANCE(A21,""price"")"),5.02) -> 5.02 | H21: =IFERROR(__xludf.DUMMYFUNCTION("(GOOGLEFINANCE(A21,""high52"") + GOOGLEFINANCE(A21,""low52""))/2"),5.505) -> 5.505 | I21: =IFERROR(__xludf.DUMMYFUNCTION("GOOGLEFINANCE(A21,""changepct"")"),-3.28) -> -3.28 | J21: =IFERROR(__xludf.DUMMYFUNCTION("GOOGLEFINANCE(A21,""volume"")"),143563.0) -> 143563 | K21: =E21*F21 -> 6.4866667 | L21: =IFERROR(SUMIFS(COMPRAS!G:G,COMPRAS!A:A,B21),0) -> 8.310211 | M21: =E21*G21 -> 5.02 | N21: {=IF(INDIRECT("'"&A$21&"'!"&"B12") ="",INDIRECT("'"&A$21&"'!"&"C12"),INDIRECT("'"&A$21&"'!"&"B12"))} -> 0.0368 | O21: {=IFERROR(AVERAGE(INDIRECT("'"&A$21&"'!"&"B12:F12")),"")} -> 0.03775 | P21: {=IF(INDIRECT("'"&A$21&"'!"&"B17") ="",INDIRECT("'"&A$21&"'!"&"C17"),INDIRECT("'"&A$21&"'!"&"B17"))} -> 17.49 | Q21: {=IFERROR(AVERAGE(INDIRECT("'"&A$21&"'!"&"B17:F17")),0)} -> 17.485 | R21: {=IF(INDIRECT("'"&A$21&"'!"&"B10") ="",INDIRECT("'"&A$21&"'!"&"C10"),INDIRECT("'"&A$21&"'!"&"B10"))} -> 0.0868 | S21: {=IFERROR(AVERAGE(INDIRECT("'"&A$21&"'!"&"B10:F10")),0)} -> 0.01736 | T21: =R21*4 -> 0.3472 | U21: =S21*4 -> 0.06944 | V21: {=IF(INDIRECT("'"&A$21&"'!"&"B15") ="",INDIRECT("'"&A$21&"'!"&"C15"),INDIRECT("'"&A$21&"'!"&"B15"))} -> 0.2454 | W21: {=IFERROR(AVERAGE(INDIRECT("'"&A$21&"'!"&"B15:F15")),"")} -> 0.26215 | X21: {=IF(INDIRECT("'"&A$21&"'!"&"B5") ="",INDIRECT("'"&A$21&"'!"&"C5"),INDIRECT("'"&A$21&"'!"&"B5"))} -> 0.7935 | Y21: {=IFERROR(AVERAGE(INDIRECT("'"&A$21&"'!"&"B5:F5")),0)} -> 0.83485 | Z21: {=IF(INDIRECT("'"&A$21&"'!"&"B7") ="",INDIRECT("'"&A$21&"'!"&"C7"),INDIRECT("'"&A$21&"'!"&"B7"))} -> 0.2794 | AA21: {=IFERROR(AVERAGE(INDIRECT("'"&A$21&"'!"&"B7:F7")),0)} -> 0.2711 | AB21: =IFERROR((G21/(L21/E21))-1,"") -> -0.39592388 | AC21: =IFERROR(U21/G21,"") -> 0.013832669 | AD21: =IFERROR(IF(M21-L21=0,"",M21-L21),"") -> -3.290211 | AE21: =IFERROR(IF(M21-K21=0,"",M21-K21),"") -> -1.4666667 | AF21: =IF(P21>0,IFERROR((P21/G21)-1,""),"") -> 2.4840637 | AG21: =IFERROR(T21/G21,"") -> 0.069163347 | AI21: {=IF(INDIRECT("'"&A$21&"'!"&"B16") ="",INDIRECT("'"&A$21&"'!"&"C16"),INDIRECT("'"&A$21&"'!"&"B16"))} -> 0 | AJ21: {=IFERROR(AVERAGE(INDIRECT("'"&A$21&"'!"&"B16:F16")),"")} -> 0 | AK21: =AVERAGE(AG21:AJ21) -> 0.023054449 | AL21: =IFERROR(IF(R21*E21=0,"",R21*E21),"") -> 0.0868 | AM21: =IFERROR(IF(S21*E21=0,"",S21*E21),"") -> 0.01736 | AN21: =IFERROR(IF(T21*E21=0,"",T21*E21),"") -> 0.3472 | AO21: =IFERROR(IF(U21*E21=0,"",U21*E21),"") -> 0.06944 | AP21: =IF(AC21*D21=0,"",AC21*D21) -> 3.9297356e-05
A22: FIBRAPL14 | B22: FIBRA PROLOGIS | C22: {=IF(INDIRECT("'"&A$22&"'!"&"B10") ="",INDIRECT("'"&A$22&"'!"&"C1"),INDIRECT("'"&A$22&"'!"&"B1"))} -> 2023 Q1 | D22: =IFERROR(E22/SUM(E13:E35),0) -> 0 | E22: =SUMIFS(COMPRAS!B:B,COMPRAS!A:A,B22) -> 0 | F22: =IFERROR(AVERAGEIFS(COMPRAS!C:C,COMPRAS!A:A,B22),0) -> 0 | G22: =IFERROR(__xludf.DUMMYFUNCTION("GOOGLEFINANCE(A22,""price"")"),79.66) -> 79.66 | H22: =IFERROR(__xludf.DUMMYFUNCTION("(GOOGLEFINANCE(A22,""high52"") + GOOGLEFINANCE(A22,""low52""))/2"),75.215) -> 75.215 | I22: =IFERROR(__xludf.DUMMYFUNCTION("GOOGLEFINANCE(A22,""changepct"")"),2.18) -> 2.18 | J22: =IFERROR(__xludf.DUMMYFUNCTION("GOOGLEFINANCE(A22,""volume"")"),525879.0) -> 525879 | K22: =E22*F22 -> 0 | L22: =IFERROR(SUMIFS(COMPRAS!G:G,COMPRAS!A:A,B22),0) -> 0 | M22: =E22*G22 -> 0 | N22: {=IF(INDIRECT("'"&A$22&"'!"&"B12") ="",INDIRECT("'"&A$22&"'!"&"C12"),INDIRECT("'"&A$22&"'!"&"B12"))} -> 0.0707 | O22: {=IFERROR(AVERAGE(INDIRECT("'"&A$22&"'!"&"B12:F12")),"")} -> 0.066233333 | P22: {=IF(INDIRECT("'"&A$22&"'!"&"B17") ="",INDIRECT("'"&A$22&"'!"&"C17"),INDIRECT("'"&A$22&"'!"&"B17"))} -> 54.51 | Q22: {=IFERROR(AVERAGE(INDIRECT("'"&A$22&"'!"&"B17:F17")),0)} -> 58.96 | R22: {=IF(INDIRECT("'"&A$22&"'!"&"B10") ="",INDIRECT("'"&A$22&"'!"&"C10"),INDIRECT("'"&A$22&"'!"&"B10"))} -> 0.85 | S22: {=IFERROR(AVERAGE(INDIRECT("'"&A$22&"'!"&"B10:F10")),0)} -> 0.644 | T22: =R22*4 -> 3.4 | U22: =S22*4 -> 2.576 | V22: {=IF(INDIRECT("'"&A$22&"'!"&"B15") ="",INDIRECT("'"&A$22&"'!"&"C15"),INDIRECT("'"&A$22&"'!"&"B15"))} -> 0.2278 | W22: {=IFERROR(AVERAGE(INDIRECT("'"&A$22&"'!"&"B15:F15")),"")} -> 0.24116667 | X22: {=IF(INDIRECT("'"&A$22&"'!"&"B5") ="",INDIRECT("'"&A$22&"'!"&"C5"),INDIRECT("'"&A$22&"'!"&"B5"))} -> 0.8657 | Y22: {=IFERROR(AVERAGE(INDIRECT("'"&A$22&"'!"&"B5:F5")),0)} -> 0.86852 | Z22: {=IF(INDIRECT("'"&A$22&"'!"&"B7") ="",INDIRECT("'"&A$22&"'!"&"C7"),INDIRECT("'"&A$22&"'!"&"B7"))} -> 0.6527 | AA22: {=IFERROR(AVERAGE(INDIRECT("'"&A$22&"'!"&"B7:F7")),0)} -> 0.5969 | AB22: =IFERROR((G22/(L22/E22))-1,"") | AC22: =IFERROR(U22/G22,"") -> 0.032337434 | AD22: =IFERROR(IF(M22-L22=0,"",M22-L22),"") | AE22: =IFERROR(IF(M22-K22=0,"",M22-K22),"") | AF22: =IF(P22>0,IFERROR((P22/G22)-1,""),"") -> -0.3157168 | AG22: =IFERROR(T22/G22,"") -> 0.042681396 | AI22: {=IF(INDIRECT("'"&A$22&"'!"&"B16") ="",INDIRECT("'"&A$22&"'!"&"C16"),INDIRECT("'"&A$22&"'!"&"B16"))} -> 0.035 | AJ22: {=IFERROR(AVERAGE(INDIRECT("'"&A$22&"'!"&"B16:F16")),"")} -> 0.0359 | AK22: =AVERAGE(AG22:AJ22) -> 0.037860465 | AL22: =IFERROR(IF(R22*E22=0,"",R22*E22),"") | AM22: =IFERROR(IF(S22*E22=0,"",S22*E22),"") | AN22: =IFERROR(IF(T22*E22=0,"",T22*E22),"") | AO22: =IFERROR(IF(U22*E22=0,"",U22*E22),"") | AP22: =IF(AC22*D22=0,"",AC22*D22)
A23: TERRA13 | B23: FIBRA TERRAFINA | C23: {=IF(INDIRECT("'"&A$23&"'!"&"B10") ="",INDIRECT("'"&A$23&"'!"&"C1"),INDIRECT("'"&A$23&"'!"&"B1"))} -> 2023 Q1 | D23: =IFERROR(E23/SUM(E13:E35),0) -> 0 | E23: =SUMIFS(COMPRAS!B:B,COMPRAS!A:A,B23) -> 0 | F23: =IFERROR(AVERAGEIFS(COMPRAS!C:C,COMPRAS!A:A,B23),0) -> 0 | G23: =IFERROR(__xludf.DUMMYFUNCTION("GOOGLEFINANCE(A23,""price"")"),"#N/A") -> #N/A | H23: =IFERROR(__xludf.DUMMYFUNCTION("(GOOGLEFINANCE(A23,""high52"") + GOOGLEFINANCE(A23,""low52""))/2"),"#N/A") -> #N/A | I23: =IFERROR(__xludf.DUMMYFUNCTION("GOOGLEFINANCE(A23,""changepct"")"),"#N/A") -> #N/A | J23: =IFERROR(__xludf.DUMMYFUNCTION("GOOGLEFINANCE(A23,""volume"")"),"#N/A") -> #N/A | K23: =E23*F23 -> 0 | L23: =IFERROR(SUMIFS(COMPRAS!G:G,COMPRAS!A:A,B23),0) -> 0 | M23: =E23*G23 -> #N/A | N23: {=IF(INDIRECT("'"&A$23&"'!"&"B12") ="",INDIRECT("'"&A$23&"'!"&"C12"),INDIRECT("'"&A$23&"'!"&"B12"))} -> 0.0774 | O23: {=IFERROR(AVERAGE(INDIRECT("'"&A$23&"'!"&"B12:F12")),"")} -> 0.067433333 | P23: {=IF(INDIRECT("'"&A$23&"'!"&"B17") ="",INDIRECT("'"&A$23&"'!"&"C17"),INDIRECT("'"&A$23&"'!"&"B17"))} -> 43.67 | Q23: {=IFERROR(AVERAGE(INDIRECT("'"&A$23&"'!"&"B17:F17")),0)} -> 47.066667 | R23: {=IF(INDIRECT("'"&A$23&"'!"&"B10") ="",INDIRECT("'"&A$23&"'!"&"C10"),INDIRECT("'"&A$23&"'!"&"B10"))} -> 0.47 | S23: {=IFERROR(AVERAGE(INDIRECT("'"&A$23&"'!"&"B10:F10")),0)} -> 0.472 | T23: =R23*4 -> 1.88 | U23: =S23*4 -> 1.888 | V23: {=IF(INDIRECT("'"&A$23&"'!"&"B15") ="",INDIRECT("'"&A$23&"'!"&"C15"),INDIRECT("'"&A$23&"'!"&"B15"))} -> 0.3123 | W23: {=IFERROR(AVERAGE(INDIRECT("'"&A$23&"'!"&"B15:F15")),"")} -> 0.30933333 | X23: {=IF(INDIRECT("'"&A$23&"'!"&"B5") ="",INDIRECT("'"&A$23&"'!"&"C5"),INDIRECT("'"&A$23&"'!"&"B5"))} -> 0.9297 | Y23: {=IFERROR(AVERAGE(INDIRECT("'"&A$23&"'!"&"B5:F5")),0)} -> 0.92722 | Z23: {=IF(INDIRECT("'"&A$23&"'!"&"B7") ="",INDIRECT("'"&A$23&"'!"&"C7"),INDIRECT("'"&A$23&"'!"&"B7"))} -> 0.5914 | AA23: {=IFERROR(AVERAGE(INDIRECT("'"&A$23&"'!"&"B7:F7")),0)} -> 0.60364 | AB23: =IFERROR((G23/(L23/E23))-1,"") | AC23: =IFERROR(U23/G23,"") | AD23: =IFERROR(IF(M23-L23=0,"",M23-L23),"") | AE23: =IFERROR(IF(M23-K23=0,"",M23-K23),"") | AF23: =IF(P23>0,IFERROR((P23/G23)-1,""),"") | AG23: =IFERROR(T23/G23,"") | AI23: {=IF(INDIRECT("'"&A$23&"'!"&"B16") ="",INDIRECT("'"&A$23&"'!"&"C16"),INDIRECT("'"&A$23&"'!"&"B16"))} -> 0.0575 | AJ23: {=AVERAGE(INDIRECT("'"&A$23&"'!"&"B16:F16"))} -> 0.0587 | AK23: =AVERAGE(AG23:AJ23) -> 0.0581 | AL23: =IFERROR(IF(R23*E23=0,"",R23*E23),"") | AM23: =IFERROR(IF(S23*E23=0,"",S23*E23),"") | AN23: =IFERROR(IF(T23*E23=0,"",T23*E23),"") | AO23: =IFERROR(IF(U23*E23=0,"",U23*E23),"") | AP23: =IF(AC23*D23=0,"",AC23*D23)
A24: FIHO12 | B24: FIBRA HOTEL | C24: {=IF(INDIRECT("'"&A$24&"'!"&"B10") ="",INDIRECT("'"&A$24&"'!"&"C1"),INDIRECT("'"&A$24&"'!"&"B1"))} -> 2023 Q1 | D24: =IFERROR(E24/SUM(E13:E35),0) -> 0 | E24: =SUMIFS(COMPRAS!B:B,COMPRAS!A:A,B24) -> 0 | F24: =IFERROR(AVERAGEIFS(COMPRAS!C:C,COMPRAS!A:A,B24),0) -> 0 | G24: =IFERROR(__xludf.DUMMYFUNCTION("GOOGLEFINANCE(A24,""price"")"),7.8) -> 7.8 | H24: =IFERROR(__xludf.DUMMYFUNCTION("(GOOGLEFINANCE(A24,""high52"") + GOOGLEFINANCE(A24,""low52""))/2"),8.684999999999999) -> 8.685 | I24: =IFERROR(__xludf.DUMMYFUNCTION("GOOGLEFINANCE(A24,""changepct"")"),1.96) -> 1.96 | J24: =IFERROR(__xludf.DUMMYFUNCTION("GOOGLEFINANCE(A24,""volume"")"),41200.0) -> 41200 | K24: =E24*F24 -> 0 | L24: =IFERROR(SUMIFS(COMPRAS!G:G,COMPRAS!A:A,B24),0) -> 0 | M24: =E24*G24 -> 0 | N24: {=IF(INDIRECT("'"&A$24&"'!"&"B12") ="",INDIRECT("'"&A$24&"'!"&"C12"),INDIRECT("'"&A$24&"'!"&"B12"))} -> 0.1174 | O24: {=IFERROR(AVERAGE(INDIRECT("'"&A$24&"'!"&"B12:F12")),"")} -> 0.11125 | P24: {=IF(INDIRECT("'"&A$24&"'!"&"B17") ="",INDIRECT("'"&A$24&"'!"&"C17"),INDIRECT("'"&A$24&"'!"&"B17"))} -> 14.79 | Q24: {=IFERROR(AVERAGE(INDIRECT("'"&A$24&"'!"&"B17:F17")),0)} -> 14.825 | R24: {=IF(INDIRECT("'"&A$24&"'!"&"B10") ="",INDIRECT("'"&A$24&"'!"&"C10"),INDIRECT("'"&A$24&"'!"&"B10"))} -> 0.125 | S24: {=IFERROR(AVERAGE(INDIRECT("'"&A$24&"'!"&"B10:F10")),0)} -> 0.025 | T24: =R24*4 -> 0.5 | U24: =S24*4 -> 0.1 | V24: {=IF(INDIRECT("'"&A$24&"'!"&"B15") ="",INDIRECT("'"&A$24&"'!"&"C15"),INDIRECT("'"&A$24&"'!"&"B15"))} -> 0.2574 | W24: {=IFERROR(AVERAGE(INDIRECT("'"&A$24&"'!"&"B15:F15")),"")} -> 0.26785 | X24: {=IF(INDIRECT("'"&A$24&"'!"&"B5") ="",INDIRECT("'"&A$24&"'!"&"C5"),INDIRECT("'"&A$24&"'!"&"B5"))} -> 0.3613 | Y24: {=IFERROR(AVERAGE(INDIRECT("'"&A$24&"'!"&"B5:F5")),0)} -> 0.31675 | Z24: {=IF(INDIRECT("'"&A$24&"'!"&"B7") ="",INDIRECT("'"&A$24&"'!"&"C7"),INDIRECT("'"&A$24&"'!"&"B7"))} -> 0.2118 | AA24: {=IFERROR(AVERAGE(INDIRECT("'"&A$24&"'!"&"B7:F7")),0)} -> 0.169575 | AB24: =IFERROR((G24/(L24/E24))-1,"") | AC24: =IFERROR(U24/G24,"") -> 0.012820513 | AD24: =IFERROR(IF(M24-L24=0,"",M24-L24),"") | AE24: =IFERROR(IF(M24-K24=0,"",M24-K24),"") | AF24: =IF(P24>0,IFERROR((P24/G24)-1,""),"") -> 0.89615385 | AG24: =IFERROR(T24/G24,"") -> 0.064102564 | AI24: {=IF(INDIRECT("'"&A$24&"'!"&"B16") ="",INDIRECT("'"&A$24&"'!"&"C16"),INDIRECT("'"&A$24&"'!"&"B16"))} -> 0.0105 | AJ24: {=IFERROR(AVERAGE(INDIRECT("'"&A$24&"'!"&"B16:F16")),"")} -> 0.0035 | AK24: =AVERAGE(AG24:AJ24) -> 0.026034188 | AL24: =IFERROR(IF(R24*E24=0,"",R24*E24),"") | AM24: =IFERROR(IF(S24*E24=0,"",S24*E24),"") | AN24: =IFERROR(IF(T24*E24=0,"",T24*E24),"") | AO24: =IFERROR(IF(U24*E24=0,"",U24*E24),"") | AP24: =IF(AC24*D24=0,"",AC24*D24)
A25: EDUCA18 | B25: FIBRA EDUCA | C25: {=IF(INDIRECT("'"&A$25&"'!"&"B10") ="",INDIRECT("'"&A$25&"'!"&"C1"),INDIRECT("'"&A$25&"'!"&"B1"))} -> 2023 Q1 | D25: =IFERROR(E25/SUM(E13:E35),0) -> 0 | E25: =SUMIFS(COMPRAS!B:B,COMPRAS!A:A,B25) -> 0 | F25: =IFERROR(AVERAGEIFS(COMPRAS!C:C,COMPRAS!A:A,B25),0) -> 0 | G25: =IFERROR(__xludf.DUMMYFUNCTION("GOOGLEFINANCE(A25,""price"")"),59.01) -> 59.01 | H25: =IFERROR(__xludf.DUMMYFUNCTION("(GOOGLEFINANCE(A25,""high52"") + GOOGLEFINANCE(A25,""low52""))/2"),53.254999999999995) -> 53.255 | I25: =IFERROR(__xludf.DUMMYFUNCTION("GOOGLEFINANCE(A25,""changepct"")"),0.0) -> 0 | J25: =IFERROR(__xludf.DUMMYFUNCTION("GOOGLEFINANCE(A25,""volume"")"),0.0) -> 0 | K25: =E25*F25 -> 0 | L25: =IFERROR(SUMIFS(COMPRAS!G:G,COMPRAS!A:A,B25),0) -> 0 | M25: =E25*G25 -> 0 | N25: {=IF(INDIRECT("'"&A$25&"'!"&"B12") ="",INDIRECT("'"&A$25&"'!"&"C12"),INDIRECT("'"&A$25&"'!"&"B12"))} -> 0.1141 | O25: {=IFERROR(AVERAGE(INDIRECT("'"&A$25&"'!"&"B12:F12")),"")} -> 0.117 | P25: {=IF(INDIRECT("'"&A$25&"'!"&"B17") ="",INDIRECT("'"&A$25&"'!"&"C17"),INDIRECT("'"&A$25&"'!"&"B17"))} -> 25.3 | Q25: {=IFERROR(AVERAGE(INDIRECT("'"&A$25&"'!"&"B17:F17")),0)} -> 24.75 | R25: {=IF(INDIRECT("'"&A$25&"'!"&"B10") ="",INDIRECT("'"&A$25&"'!"&"C10"),INDIRECT("'"&A$25&"'!"&"B10"))} -> 0.5702 | S25: {=IFERROR(AVERAGE(INDIRECT("'"&A$25&"'!"&"B10:F10")),0)} -> 0.5706034 | T25: =R25*4 -> 2.2808 | U25: =S25*4 -> 2.2824136 | V25: {=IF(INDIRECT("'"&A$25&"'!"&"B15") ="",INDIRECT("'"&A$25&"'!"&"C15"),INDIRECT("'"&A$25&"'!"&"B15"))} -> 0.1529 | W25: {=IFERROR(AVERAGE(INDIRECT("'"&A$25&"'!"&"B15:F15")),"")} -> 0.1556 | X25: {=IF(INDIRECT("'"&A$25&"'!"&"B5") ="",INDIRECT("'"&A$25&"'!"&"C5"),INDIRECT("'"&A$25&"'!"&"B5"))} -> 0.8683 | Y25: {=IFERROR(AVERAGE(INDIRECT("'"&A$25&"'!"&"B5:F5")),0)} -> 0.869125 | Z25: {=IF(INDIRECT("'"&A$25&"'!"&"B7") ="",INDIRECT("'"&A$25&"'!"&"C7"),INDIRECT("'"&A$25&"'!"&"B7"))} -> 0.7189 | AA25: {=IFERROR(AVERAGE(INDIRECT("'"&A$25&"'!"&"B7:F7")),0)} -> 0.789875 | AB25: =IFERROR((G25/(L25/E25))-1,"") | AC25: =IFERROR(U25/G25,"") -> 0.038678421 | AD25: =IFERROR(IF(M25-L25=0,"",M25-L25),"") | AE25: =IFERROR(IF(M25-K25=0,"",M25-K25),"") | AF25: =IF(P25>0,IFERROR((P25/G25)-1,""),"") -> -0.57125911 | AG25: =IFERROR(T25/G25,"") -> 0.038651076 | AI25: {=IF(INDIRECT("'"&A$25&"'!"&"B16") ="",INDIRECT("'"&A$25&"'!"&"C16"),INDIRECT("'"&A$25&"'!"&"B16"))} -> 0.0456 | AJ25: {=AVERAGE(INDIRECT("'"&A$25&"'!"&"B16:F16"))} -> 0.04535 | AK25: =AVERAGE(AG25:AJ25) -> 0.043200359 | AL25: =IFERROR(IF(R25*E25=0,"",R25*E25),"") | AM25: =IFERROR(IF(S25*E25=0,"",S25*E25),"") | AN25: =IFERROR(IF(T25*E25=0,"",T25*E25),"") | AO25: =IFERROR(IF(U25*E25=0,"",U25*E25),"") | AP25: =IF(AC25*D25=0,"",AC25*D25)
A26: SOMA21 | B26: FIBRA SOMA | C26: {=IF(INDIRECT("'"&A$26&"'!"&"B10") ="",INDIRECT("'"&A$26&"'!"&"C1"),INDIRECT("'"&A$26&"'!"&"B1"))} -> 2023 Q1 | D26: =IFERROR(E26/SUM(E13:E35),0) -> 0 | E26: =SUMIFS(COMPRAS!B:B,COMPRAS!A:A,B26) -> 0 | F26: =IFERROR(AVERAGEIFS(COMPRAS!C:C,COMPRAS!A:A,B26),0) -> 0 | G26: =IFERROR(__xludf.DUMMYFUNCTION("GOOGLEFINANCE(A26,""price"")"),50.0) -> 50 | H26: =IFERROR(__xludf.DUMMYFUNCTION("IFERROR(G26,(GOOGLEFINANCE(A26,""high52"") + GOOGLEFINANCE(A26,""low52""))/2)"),50.0) -> 50 | I26: =IFERROR(__xludf.DUMMYFUNCTION("IF(GOOGLEFINANCE(A26,""changepct"") <=-100,0,GOOGLEFINANCE(A26,""changepct"") )"),0.0) -> 0 | J26: =IFERROR(__xludf.DUMMYFUNCTION("GOOGLEFINANCE(A26,""volume"")"),0.0) -> 0 | K26: =E26*F26 -> 0 | L26: =IFERROR(SUMIFS(COMPRAS!G:G,COMPRAS!A:A,B26),0) -> 0 | M26: =E26*G26 -> 0 | N26: {=IF(INDIRECT("'"&A$26&"'!"&"B12") ="",INDIRECT("'"&A$26&"'!"&"C12"),INDIRECT("'"&A$26&"'!"&"B12"))} -> 0.0365 | O26: {=IFERROR(AVERAGE(INDIRECT("'"&A$26&"'!"&"B12:F12")),"")} -> 0.0367 | P26: {=IF(INDIRECT("'"&A$26&"'!"&"B17") ="",INDIRECT("'"&A$26&"'!"&"C17"),INDIRECT("'"&A$26&"'!"&"B17"))} -> 49.5 | Q26: {=IFERROR(AVERAGE(INDIRECT("'"&A$26&"'!"&"B17:F17")),0)} -> 50.845 | R26: {=IF(INDIRECT("'"&A$26&"'!"&"B10") ="",INDIRECT("'"&A$26&"'!"&"C10"),INDIRECT("'"&A$26&"'!"&"B10"))} -> 0 | S26: {=IFERROR(AVERAGE(INDIRECT("'"&A$26&"'!"&"B10:F10")),0)} -> 0.166 | T26: =R26*4 -> 0 | U26: =S26*4 -> 0.664 | V26: {=IF(INDIRECT("'"&A$26&"'!"&"B15") ="",INDIRECT("'"&A$26&"'!"&"C15"),INDIRECT("'"&A$26&"'!"&"B15"))} -> 0.2519 | W26: {=IFERROR(AVERAGE(INDIRECT("'"&A$26&"'!"&"B15:F15")),"")} -> 0.24505 | X26: {=IF(INDIRECT("'"&A$26&"'!"&"B5") ="",INDIRECT("'"&A$26&"'!"&"C5"),INDIRECT("'"&A$26&"'!"&"B5"))} -> 0.7701 | Y26: {=IFERROR(AVERAGE(INDIRECT("'"&A$26&"'!"&"B5:F5")),0)} -> 0.71144 | Z26: {=IF(INDIRECT("'"&A$26&"'!"&"B7") ="",INDIRECT("'"&A$26&"'!"&"C7"),INDIRECT("'"&A$26&"'!"&"B7"))} -> 0.407 | AA26: {=IFERROR(AVERAGE(INDIRECT("'"&A$26&"'!"&"B7:F7")),0)} -> 0.30386 | AB26: =IFERROR((G26/(L26/E26))-1,"") | AC26: =IFERROR(U26/G26,"") -> 0.01328 | AD26: =IFERROR(IF(M26-L26=0,"",M26-L26),"") | AE26: =IFERROR(IF(M26-K26=0,"",M26-K26),"") | AF26: =IF(P26>0,IFERROR((P26/G26)-1,""),"") -> -0.01 | AG26: =IFERROR(T26/G26,"") -> 0 | AI26: {=IF(INDIRECT("'"&A$26&"'!"&"B16") ="",INDIRECT("'"&A$26&"'!"&"C16"),INDIRECT("'"&A$26&"'!"&"B16"))} -> 0 | AJ26: {=IFERROR(AVERAGE(INDIRECT("'"&A$26&"'!"&"B16:F16")),"")} -> 0 | AK26: =AVERAGE(AG26:AJ26) -> 0 | AL26: =IFERROR(IF(R26*E26=0,"",R26*E26),"") | AM26: =IFERROR(IF(S26*E26=0,"",S26*E26),"") | AN26: =IFERROR(IF(T26*E26=0,"",T26*E26),"") | AO26: =IFERROR(IF(U26*E26=0,"",U26*E26),"") | AP26: =IF(AC26*D26=0,"",AC26*D26)
A27: STORAGE18 | B27: FIBRA STORAGE | C27: {=IF(INDIRECT("'"&A$27&"'!"&"B10") ="",INDIRECT("'"&A$27&"'!"&"C1"),INDIRECT("'"&A$27&"'!"&"B1"))} -> 2022 Q4 | D27: =IFERROR(E27/SUM(E13:E35),0) -> 0 | E27: =SUMIFS(COMPRAS!B:B,COMPRAS!A:A,B27) -> 0 | F27: =IFERROR(AVERAGEIFS(COMPRAS!C:C,COMPRAS!A:A,B27),0) -> 0 | G27: =IFERROR(__xludf.DUMMYFUNCTION("GOOGLEFINANCE(A27,""price"")"),24.99) -> 24.99 | H27: =IFERROR(__xludf.DUMMYFUNCTION("IFERROR(G27,(GOOGLEFINANCE(A27,""high52"") + GOOGLEFINANCE(A27,""low52""))/2)"),24.99) -> 24.99 | I27: =IFERROR(__xludf.DUMMYFUNCTION("GOOGLEFINANCE(A27,""changepct"")"),-0.08) -> -0.08 | J27: =IFERROR(__xludf.DUMMYFUNCTION("GOOGLEFINANCE(A27,""volume"")"),1293.0) -> 1293 | K27: =E27*F27 -> 0 | L27: =IFERROR(SUMIFS(COMPRAS!G:G,COMPRAS!A:A,B27),0) -> 0 | M27: =E27*G27 -> 0 | N27: {=IF(INDIRECT("'"&A$27&"'!"&"B12") ="",INDIRECT("'"&A$27&"'!"&"C12"),INDIRECT("'"&A$27&"'!"&"B12"))} -> 0.0695 | O27: {=IFERROR(AVERAGE(INDIRECT("'"&A$27&"'!"&"B12:F12")),"")} -> 0.071 | P27: {=IF(INDIRECT("'"&A$27&"'!"&"B17") ="",INDIRECT("'"&A$27&"'!"&"C17"),INDIRECT("'"&A$27&"'!"&"B17"))} -> 21.09 | Q27: {=IFERROR(AVERAGE(INDIRECT("'"&A$27&"'!"&"B17:F17")),0)} -> 20.61 | R27: {=IF(INDIRECT("'"&A$27&"'!"&"B10") ="",INDIRECT("'"&A$27&"'!"&"C10"),INDIRECT("'"&A$27&"'!"&"B10"))} -> 0 | S27: {=IFERROR(AVERAGE(INDIRECT("'"&A$27&"'!"&"B10:F10")),0)} -> 0.0875 | T27: =R27*4 -> 0 | U27: =S27*4 -> 0.35 | V27: {=IF(INDIRECT("'"&A$27&"'!"&"B15") ="",INDIRECT("'"&A$27&"'!"&"C15"),INDIRECT("'"&A$27&"'!"&"B15"))} -> 0.2267 | W27: {=IFERROR(AVERAGE(INDIRECT("'"&A$27&"'!"&"B15:F15")),"")} -> 0.2319 | X27: {=IF(INDIRECT("'"&A$27&"'!"&"B5") ="",INDIRECT("'"&A$27&"'!"&"C5"),INDIRECT("'"&A$27&"'!"&"B5"))} -> 0.7703 | Y27: {=IFERROR(AVERAGE(INDIRECT("'"&A$27&"'!"&"B5:F5")),0)} -> 0.76485 | Z27: {=IF(INDIRECT("'"&A$27&"'!"&"B7") ="",INDIRECT("'"&A$27&"'!"&"C7"),INDIRECT("'"&A$27&"'!"&"B7"))} -> 0.4378 | AA27: {=IFERROR(AVERAGE(INDIRECT("'"&A$27&"'!"&"B7:F7")),0)} -> 0.334975 | AB27: =IFERROR((G27/(L27/E27))-1,"") | AC27: =IFERROR(U27/G27,"") -> 0.014005602 | AD27: =IFERROR(IF(M27-L27=0,"",M27-L27),"") | AE27: =IFERROR(IF(M27-K27=0,"",M27-K27),"") | AF27: =IF(P27>0,IFERROR((P27/G27)-1,""),"") -> -0.15606243 | AG27: =IFERROR(T27/G27,"") -> 0 | AI27: {=IF(INDIRECT("'"&A$27&"'!"&"B16") ="",INDIRECT("'"&A$27&"'!"&"C16"),INDIRECT("'"&A$27&"'!"&"B16"))} -> 0 | AJ27: {=IFERROR(AVERAGE(INDIRECT("'"&A$27&"'!"&"B16:F16")),"")} -> 0 | AK27: =AVERAGE(AG27:AJ27) -> 0 | AL27: =IFERROR(IF(R27*E27=0,"",R27*E27),"") | AM27: =IFERROR(IF(S27*E27=0,"",S27*E27),"") | AN27: =IFERROR(IF(T27*E27=0,"",T27*E27),"") | AO27: =IFERROR(IF(U27*E27=0,"",U27*E27),"") | AP27: =IF(AC27*D27=0,"",AC27*D27)
A28: FSITES20 | B28: FIBRA TELESITES | C28: {=IF(INDIRECT("'"&A$28&"'!"&"B10") ="",INDIRECT("'"&A$28&"'!"&"C1"),INDIRECT("'"&A$28&"'!"&"B1"))} -> 2023 Q1 | D28: =IFERROR(E28/SUM(E13:E35),0) -> 0 | E28: =SUMIFS(COMPRAS!B:B,COMPRAS!A:A,B28) -> 0 | F28: =IFERROR(AVERAGEIFS(COMPRAS!C:C,COMPRAS!A:A,B28),0) -> 0 | G28: =IFERROR(__xludf.DUMMYFUNCTION("GOOGLEFINANCE(A28,""price"")"),26.0) -> 26 | H28: =IFERROR(__xludf.DUMMYFUNCTION("IFERROR(G28,(GOOGLEFINANCE(A28,""high52"") + GOOGLEFINANCE(A28,""low52""))/2)"),26.0) -> 26 | I28: =IFERROR(__xludf.DUMMYFUNCTION("GOOGLEFINANCE(A28,""changepct"")"),0.0) -> 0 | J28: =IFERROR(__xludf.DUMMYFUNCTION("GOOGLEFINANCE(A28,""volume"")"),0.0) -> 0 | K28: =E28*F28 -> 0 | L28: =IFERROR(SUMIFS(COMPRAS!G:G,COMPRAS!A:A,B28),0) -> 0 | M28: =E28*G28 -> 0 | N28: {=IF(INDIRECT("'"&A$28&"'!"&"B12") ="",INDIRECT("'"&A$28&"'!"&"C12"),INDIRECT("'"&A$28&"'!"&"B12"))} | O28: {=IFERROR(AVERAGE(INDIRECT("'"&A$28&"'!"&"B12:F12")),"")} -> 0.1113 | P28: {=IF(INDIRECT("'"&A$28&"'!"&"B17") ="",INDIRECT("'"&A$28&"'!"&"C17"),INDIRECT("'"&A$28&"'!"&"B17"))} | Q28: {=IFERROR(AVERAGE(INDIRECT("'"&A$28&"'!"&"B17:F17")),"")} -> 17.68 | R28: {=IF(INDIRECT("'"&A$28&"'!"&"B10") ="",INDIRECT("'"&A$28&"'!"&"C10"),INDIRECT("'"&A$28&"'!"&"B10"))} -> 0.147633 | S28: {=IFERROR(AVERAGE(INDIRECT("'"&A$28&"'!"&"B10:F10")),0)} -> 0.181872 | T28: =R28*4 -> 0.590532 | U28: =S28*4 -> 0.727488 | V28: {=IF(INDIRECT("'"&A$28&"'!"&"B15") ="",INDIRECT("'"&A$28&"'!"&"C15"),INDIRECT("'"&A$28&"'!"&"B15"))} | W28: {=IFERROR(AVERAGE(INDIRECT("'"&A$28&"'!"&"B15:F15")),"")} | X28: {=IF(INDIRECT("'"&A$28&"'!"&"B5") ="",INDIRECT("'"&A$28&"'!"&"C5"),INDIRECT("'"&A$28&"'!"&"B5"))} | Y28: {=IFERROR(AVERAGE(INDIRECT("'"&A$28&"'!"&"B5:F5")),"")} | Z28: {=IF(INDIRECT("'"&A$28&"'!"&"B7") ="",INDIRECT("'"&A$28&"'!"&"C7"),INDIRECT("'"&A$28&"'!"&"B7"))} | AA28: {=IFERROR(AVERAGE(INDIRECT("'"&A$28&"'!"&"B7:F7")),"")} | AB28: =IFERROR((G28/(L28/E28))-1,"") | AC28: =IFERROR(U28/G28,"") -> 0.027980308 | AD28: =IFERROR(IF(M28-L28=0,"",M28-L28),"") | AE28: =IFERROR(IF(M28-K28=0,"",M28-K28),"") | AF28: =IF(P28>0,IFERROR((P28/G28)-1,""),"") | AG28: =IFERROR(T28/G28,"") -> 0.022712769 | AI28: {=IF(INDIRECT("'"&A$28&"'!"&"B16") ="",INDIRECT("'"&A$28&"'!"&"C16"),INDIRECT("'"&A$28&"'!"&"B16"))} -> 0.0077 | AJ28: {=IFERROR(AVERAGE(INDIRECT("'"&A$28&"'!"&"B16:F16")),"")} -> 0.00385 | AK28: =AVERAGE(AG28:AJ28) -> 0.011420923 | AL28: =IFERROR(IF(R28*E28=0,"",R28*E28),"") | AM28: =IFERROR(IF(S28*E28=0,"",S28*E28),"") | AN28: =IFERROR(IF(T28*E28=0,"",T28*E28),"") | AO28: =IFERROR(IF(U28*E28=0,"",U28*E28),"") | AP28: =IF(AC28*D28=0,"",AC28*D28)
A29: FIDEAL20 | B29: FIBRA IDEAL | C29: {=IF(INDIRECT("'"&A$29&"'!"&"B10") ="",INDIRECT("'"&A$29&"'!"&"C1"),INDIRECT("'"&A$29&"'!"&"B1"))} -> 2022 Q4 | D29: =IFERROR(E29/SUM(E13:E35),0) -> 0 | E29: =SUMIFS(COMPRAS!B:B,COMPRAS!A:A,B29) -> 0 | F29: =IFERROR(AVERAGEIFS(COMPRAS!C:C,COMPRAS!A:A,B29),0) -> 0 | G29: =IFERROR(__xludf.DUMMYFUNCTION("GOOGLEFINANCE(A29,""price"")"),68.85) -> 68.85 | H29: =IFERROR(__xludf.DUMMYFUNCTION("IFERROR(G29,(GOOGLEFINANCE(A29,""high52"") + GOOGLEFINANCE(A29,""low52""))/2)"),68.85) -> 68.85 | I29: =IFERROR(__xludf.DUMMYFUNCTION("GOOGLEFINANCE(A29,""changepct"")"),0.0) -> 0 | J29: =IFERROR(__xludf.DUMMYFUNCTION("GOOGLEFINANCE(A29,""volume"")"),0.0) -> 0 | K29: =E29*F29 -> 0 | L29: =IFERROR(SUMIFS(COMPRAS!G:G,COMPRAS!A:A,B29),0) -> 0 | M29: =E29*G29 -> 0 | N29: {=IF(INDIRECT("'"&A$29&"'!"&"B12") ="",INDIRECT("'"&A$29&"'!"&"C12"),INDIRECT("'"&A$29&"'!"&"B12"))} | O29: {=IFERROR(AVERAGE(INDIRECT("'"&A$29&"'!"&"B12:F12")),"")} | P29: {=IF(INDIRECT("'"&A$29&"'!"&"B17") ="",INDIRECT("'"&A$29&"'!"&"C17"),INDIRECT("'"&A$29&"'!"&"B17"))} | Q29: {=IFERROR(AVERAGE(INDIRECT("'"&A$29&"'!"&"B17:F17")),"")} | R29: {=IF(INDIRECT("'"&A$29&"'!"&"B10") ="",INDIRECT("'"&A$29&"'!"&"C10"),INDIRECT("'"&A$29&"'!"&"B10"))} -> 1.4136 | S29: {=IFERROR(AVERAGE(INDIRECT("'"&A$29&"'!"&"B10:F10")),"")} -> 1.3759 | T29: =R29*4 -> 5.6544 | U29: =S29*4 -> 5.5036 | V29: {=IF(INDIRECT("'"&A$29&"'!"&"B15") ="",INDIRECT("'"&A$29&"'!"&"C15"),INDIRECT("'"&A$29&"'!"&"B15"))} | W29: {=IFERROR(AVERAGE(INDIRECT("'"&A$29&"'!"&"B15:F15")),"")} | X29: {=IF(INDIRECT("'"&A$29&"'!"&"B5") ="",INDIRECT("'"&A$29&"'!"&"C5"),INDIRECT("'"&A$29&"'!"&"B5"))} | Y29: {=IFERROR(AVERAGE(INDIRECT("'"&A$29&"'!"&"B5:F5")),"")} | Z29: {=IF(INDIRECT("'"&A$29&"'!"&"B7") ="",INDIRECT("'"&A$29&"'!"&"C7"),INDIRECT("'"&A$29&"'!"&"B7"))} | AA29: {=IFERROR(AVERAGE(INDIRECT("'"&A$29&"'!"&"B7:F7")),"")} | AB29: =IFERROR((G29/(L29/E29))-1,"") | AC29: =IFERROR(U29/G29,"") -> 0.079936093 | AD29: =IFERROR(IF(M29-L29=0,"",M29-L29),"") | AE29: =IFERROR(IF(M29-K29=0,"",M29-K29),"") | AF29: =IF(P29>0,IFERROR((P29/G29)-1,""),"") | AG29: =IFERROR(T29/G29,"") -> 0.082126362 | AI29: {=IF(INDIRECT("'"&A$29&"'!"&"B16") ="",INDIRECT("'"&A$29&"'!"&"C16"),INDIRECT("'"&A$29&"'!"&"B16"))} | AJ29: {=IFERROR(AVERAGE(INDIRECT("'"&A$29&"'!"&"B16:F16")),"")} | AK29: =AVERAGE(AG29:AJ29) -> 0.082126362 | AL29: =IFERROR(IF(R29*E29=0,"",R29*E29),"") | AM29: =IFERROR(IF(S29*E29=0,"",S29*E29),"") | AN29: =IFERROR(IF(T29*E29=0,"",T29*E29),"") | AO29: =IFERROR(IF(U29*E29=0,"",U29*E29),"") | AP29: =IF(AC29*D29=0,"",AC29*D29)
A30: FEXI21 | B30: FIBRA EXI | C30: {=IF(INDIRECT("'"&A$30&"'!"&"B10") ="",INDIRECT("'"&A$30&"'!"&"C1"),INDIRECT("'"&A$30&"'!"&"B1"))} -> 2022 Q4 | D30: =IFERROR(E30/SUM(E13:E35),0) -> 0 | E30: =SUMIFS(COMPRAS!B:B,COMPRAS!A:A,B30) -> 0 | F30: =IFERROR(AVERAGEIFS(COMPRAS!C:C,COMPRAS!A:A,B30),0) -> 0 | G30: =IFERROR(__xludf.DUMMYFUNCTION("GOOGLEFINANCE(A30,""price"")"),19.48) -> 19.48 | H30: =IFERROR(__xludf.DUMMYFUNCTION("IFERROR(G30,(GOOGLEFINANCE(A30,""high52"") + GOOGLEFINANCE(A30,""low52""))/2)"),19.48) -> 19.48 | I30: =IFERROR(__xludf.DUMMYFUNCTION("GOOGLEFINANCE(A30,""changepct"")"),-0.2) -> -0.2 | J30: =IFERROR(__xludf.DUMMYFUNCTION("GOOGLEFINANCE(A30,""volume"")"),1062.0) -> 1062 | K30: =E30*F30 -> 0 | L30: =IFERROR(SUMIFS(COMPRAS!G:G,COMPRAS!A:A,B30),0) -> 0 | M30: =E30*G30 -> 0 | N30: {=IF(INDIRECT("'"&A$30&"'!"&"B12") ="",INDIRECT("'"&A$30&"'!"&"C12"),INDIRECT("'"&A$30&"'!"&"B12"))} | O30: {=IFERROR(AVERAGE(INDIRECT("'"&A$30&"'!"&"B12:F12")),"")} | P30: {=IF(INDIRECT("'"&A$30&"'!"&"B17") ="",INDIRECT("'"&A$30&"'!"&"C17"),INDIRECT("'"&A$30&"'!"&"B17"))} | Q30: {=IFERROR(AVERAGE(INDIRECT("'"&A$30&"'!"&"B17:F17")),"")} | R30: {=IF(INDIRECT("'"&A$30&"'!"&"B10") ="",INDIRECT("'"&A$30&"'!"&"C10"),INDIRECT("'"&A$30&"'!"&"B10"))} -> 0.1246 | S30: {=IFERROR(AVERAGE(INDIRECT("'"&A$30&"'!"&"B10:F10")),"")} -> 0.17365 | T30: =R30*4 -> 0.4984 | U30: =S30*4 -> 0.6946 | V30: {=IF(INDIRECT("'"&A$30&"'!"&"B15") ="",INDIRECT("'"&A$30&"'!"&"C15"),INDIRECT("'"&A$30&"'!"&"B15"))} | W30: {=IFERROR(AVERAGE(INDIRECT("'"&A$30&"'!"&"B15:F15")),"")} | X30: {=IF(INDIRECT("'"&A$30&"'!"&"B5") ="",INDIRECT("'"&A$30&"'!"&"C5"),INDIRECT("'"&A$30&"'!"&"B5"))} | Y30: {=IFERROR(AVERAGE(INDIRECT("'"&A$30&"'!"&"B5:F5")),"")} | Z30: {=IF(INDIRECT("'"&A$30&"'!"&"B7") ="",INDIRECT("'"&A$30&"'!"&"C7"),INDIRECT("'"&A$30&"'!"&"B7"))} | AA30: {=IFERROR(AVERAGE(INDIRECT("'"&A$30&"'!"&"B7:F7")),"")} | AB30: =IFERROR((G30/(L30/E30))-1,"") | AC30: =IFERROR(U30/G30,"") -> 0.035657084 | AD30: =IFERROR(IF(M30-L30=0,"",M30-L30),"") | AE30: =IFERROR(IF(M30-K30=0,"",M30-K30),"") | AF30: =IF(P30>0,IFERROR((P30/G30)-1,""),"") | AG30: =IFERROR(T30/G30,"") -> 0.025585216 | AI30: {=IF(INDIRECT("'"&A$30&"'!"&"B16") ="",INDIRECT("'"&A$30&"'!"&"C16"),INDIRECT("'"&A$30&"'!"&"B16"))} | AJ30: {=IFERROR(AVERAGE(INDIRECT("'"&A$30&"'!"&"B16:F16")),"")} | AK30: =AVERAGE(AG30:AJ30) -> 0.025585216 | AL30: =IFERROR(IF(R30*E30=0,"",R30*E30),"") | AM30: =IFERROR(IF(S30*E30=0,"",S30*E30),"") | AN30: =IFERROR(IF(T30*E30=0,"",T30*E30),"") | AO30: =IFERROR(IF(U30*E30=0,"",U30*E30),"") | AP30: =IF(AC30*D30=0,"",AC30*D30)
